Workbook

Sheet Main
C2: Date: 08/25/2026 | AQ2: Store type: | AR2: Fashion Focus | AS2: Standard | AT2: Standard | AU2: Standard | AV2: Standard | AW2: Standard | AX2: Standard | AY2: Standard
C3: Weborder project summary | AQ3: Store state: | AR3: FL | AS3: TX | AT3: OK | AU3: SC | AV3: CA | AW3: CA | AX3: TX | AY3: AZ
AQ4: Store size: | AR4: 4-Avg | AS4: 4-Avg | AT4: 2-XSm | AU4: 1-IttyBitty | AV4: 3-Sml | AW4: 4-Avg | AX4: 5-XLg | AY4: 1-IttyBitty
C5: Item information and qty to allocate per group | P5: ┌> formula to be provided | Y5: Finding the store group: | AI5: Allocating the qtys based on the store group: | AR5: Exclusions table: | BA5: Allocation qty after exclusions: | BJ5: Qty on-hand + in-transit: | BS5: Allocation before final adjustment:
C6: DCS | D6: Item | E6: Description | F6: Launch code | G6: Istatus | H6: Sale Price | I6: Case qty | J6: MDQ | K6: EBT Store | L6: Online Store | M6: EBT Mark down | N6: Prop 65 Fail | O6: Item Code | P6: DPS Code | Q6: A1 | R6: A2 | S6: A3 | T6: B | U6: C | V6: D | W6: E | Y6: DCS pattern | Z6: 201 | AA6: 301 | AB6: 392 | AC6: 402 | AD6: 442 | AE6: 450 | AF6: 501 | AG6: 543 | AI6: 201 | AJ6: 301 | AK6: 392 | AL6: 402 | AM6: 442 | AN6: 450 | AO6: 501 | AP6: 543 | AR6: 201 | AS6: 301 | AT6: 392 | AU6: 402 | AV6: 442 | AW6: 450 | AX6: 501 | AY6: 543 | BA6: 201 | BB6: 301 | BC6: 392 | BD6: 402 | BE6: 442 | BF6: 450 | BG6: 501 | BH6: 543 | BJ6: 201 | BK6: 301 | BL6: 392 | BM6: 402 | BN6: 442 | BO6: 450 | BP6: 501 | BQ6: 543 | BS6: Case qty | BT6: 201 | BU6: 301 | BV6: 392 | BW6: 402 | BX6: 442 | BY6: 450 | BZ6: 501 | CA6: 543 | CB6: DC available qty | CC6: Final alloc qty | CD6: Back stock after alloc
B7: 1 | C7: AC BA | D7: 96268 | E7: METAL PURSE-MOON PHASES GOLD | F7: 26 Summer 1 Fashion | G7: DeadSKU | H7: 19.97 | I7: 1 | J7: 2 | K7: Y | L7: Y | M7: Y | N7: Null | O7: 96268 | P7: AC BA/17-21/No | Q7: =IFERROR(INDEX(Item_Code_allocation_table!$C$4:$I$15,MATCH(Main!$O7,Item_Code_allocation_table!$B$4:$B$15,0),MATCH(Main!Q$6,Item_Code_allocation_table!$C$3:$I$3,0)), INDEX(DPS_Code_allocation_table!$C$4:$I$15,MATCH(Main!$P7,DPS_Code_allocation_table!$B$4:$B$15,0),MATCH(Main!Q$6,DPS_Code_allocation_table!$C$3:$I$3,0))) -> 16 | R7: =IFERROR(INDEX(Item_Code_allocation_table!$C$4:$I$15,MATCH(Main!$O7,Item_Code_allocation_table!$B$4:$B$15,0),MATCH(Main!R$6,Item_Code_allocation_table!$C$3:$I$3,0)), INDEX(DPS_Code_allocation_table!$C$4:$I$15,MATCH(Main!$P7,DPS_Code_allocation_table!$B$4:$B$15,0),MATCH(Main!R$6,DPS_Code_allocation_table!$C$3:$I$3,0))) -> 10 | S7: =IFERROR(INDEX(Item_Code_allocation_table!$C$4:$I$15,MATCH(Main!$O7,Item_Code_allocation_table!$B$4:$B$15,0),MATCH(Main!S$6,Item_Code_allocation_table!$C$3:$I$3,0)), INDEX(DPS_Code_allocation_table!$C$4:$I$15,MATCH(Main!$P7,DPS_Code_allocation_table!$B$4:$B$15,0),MATCH(Main!S$6,DPS_Code_allocation_table!$C$3:$I$3,0))) -> 8 | T7: =IFERROR(INDEX(Item_Code_allocation_table!$C$4:$I$15,MATCH(Main!$O7,Item_Code_allocation_table!$B$4:$B$15,0),MATCH(Main!T$6,Item_Code_allocation_table!$C$3:$I$3,0)), INDEX(DPS_Code_allocation_table!$C$4:$I$15,MATCH(Main!$P7,DPS_Code_allocation_table!$B$4:$B$15,0),MATCH(Main!T$6,DPS_Code_allocation_table!$C$3:$I$3,0))) -> 6 | U7: =IFERROR(INDEX(Item_Code_allocation_table!$C$4:$I$15,MATCH(Main!$O7,Item_Code_allocation_table!$B$4:$B$15,0),MATCH(Main!U$6,Item_Code_allocation_table!$C$3:$I$3,0)), INDEX(DPS_Code_allocation_table!$C$4:$I$15,MATCH(Main!$P7,DPS_Code_allocation_table!$B$4:$B$15,0),MATCH(Main!U$6,DPS_Code_allocation_table!$C$3:$I$3,0))) -> 5 | V7: =IFERROR(INDEX(Item_Code_allocation_table!$C$4:$I$15,MATCH(Main!$O7,Item_Code_allocation_table!$B$4:$B$15,0),MATCH(Main!V$6,Item_Code_allocation_table!$C$3:$I$3,0)), INDEX(DPS_Code_allocation_table!$C$4:$I$15,MATCH(Main!$P7,DPS_Code_allocation_table!$B$4:$B$15,0),MATCH(Main!V$6,DPS_Code_allocation_table!$C$3:$I$3,0))) -> 4 | W7: =IFERROR(INDEX(Item_Code_allocation_table!$C$4:$I$15,MATCH(Main!$O7,Item_Code_allocation_table!$B$4:$B$15,0),MATCH(Main!W$6,Item_Code_allocation_table!$C$3:$I$3,0)), INDEX(DPS_Code_allocation_table!$C$4:$I$15,MATCH(Main!$P7,DPS_Code_allocation_table!$B$4:$B$15,0),MATCH(Main!W$6,DPS_Code_allocation_table!$C$3:$I$3,0))) -> 3 | Y7: =VLOOKUP(C7,DCS_Pattern!B:C,2,FALSE) -> Pattern 02 | Z7: {=_xlfn.XLOOKUP(1,(Store_Group!$B$4:$B$1532=$Y7)*(Store_Group!$C$4:$C$1532=Z$6),Store_Group!$D$4:$D$1532,"")} -> B | AA7: {=_xlfn.XLOOKUP(1,(Store_Group!$B$4:$B$1532=$Y7)*(Store_Group!$C$4:$C$1532=AA$6),Store_Group!$D$4:$D$1532,"")} -> A3 | AB7: {=_xlfn.XLOOKUP(1,(Store_Group!$B$4:$B$1532=$Y7)*(Store_Group!$C$4:$C$1532=AB$6),Store_Group!$D$4:$D$1532,"")} -> C | AC7: {=_xlfn.XLOOKUP(1,(Store_Group!$B$4:$B$1532=$Y7)*(Store_Group!$C$4:$C$1532=AC$6),Store_Group!$D$4:$D$1532,"")} -> C | AD7: {=_xlfn.XLOOKUP(1,(Store_Group!$B$4:$B$1532=$Y7)*(Store_Group!$C$4:$C$1532=AD$6),Store_Group!$D$4:$D$1532,"")} -> A3 | AE7: {=_xlfn.XLOOKUP(1,(Store_Group!$B$4:$B$1532=$Y7)*(Store_Group!$C$4:$C$1532=AE$6),Store_Group!$D$4:$D$1532,"")} -> C | AF7: {=_xlfn.XLOOKUP(1,(Store_Group!$B$4:$B$1532=$Y7)*(Store_Group!$C$4:$C$1532=AF$6),Store_Group!$D$4:$D$1532,"")} -> C | AG7: {=_xlfn.XLOOKUP(1,(Store_Group!$B$4:$B$1532=$Y7)*(Store_Group!$C$4:$C$1532=AG$6),Store_Group!$D$4:$D$1532,"")} -> C | AI7: =INDEX($Q7:$W7,1,MATCH(Z7,$Q$6:$W$6,0)) -> 6 | AJ7: =INDEX($Q7:$W7,1,MATCH(AA7,$Q$6:$W$6,0)) -> 8 | AK7: =INDEX($Q7:$W7,1,MATCH(AB7,$Q$6:$W$6,0)) -> 5 | AL7: =INDEX($Q7:$W7,1,MATCH(AC7,$Q$6:$W$6,0)) -> 5 | AM7: =INDEX($Q7:$W7,1,MATCH(AD7,$Q$6:$W$6,0)) -> 8 | AN7: =INDEX($Q7:$W7,1,MATCH(AE7,$Q$6:$W$6,0)) -> 5 | AO7: =INDEX($Q7:$W7,1,MATCH(AF7,$Q$6:$W$6,0)) -> 5 | AP7: =INDEX($Q7:$W7,1,MATCH(AG7,$Q$6:$W$6,0)) -> 5 | AR7: Y | AS7: Y | AT7: Y | AU7: Y | AV7: Y | AW7: Y | AX7: Y | AY7: Y | BA7: 6 | BB7: 8 | BC7: 5 | BD7: 5 | BE7: 8 | BF7: 5 | BG7: 5 | BH7: 5 | BJ7: 2 | BK7: 4 | BL7: 3 | BM7: 4 | BN7: 1 | BO7: 3 | BP7: 2 | BQ7: 3 | BS7: 1 | BT7: =MAX(0,ROUND((BA7-BJ7)/$BS7,0)*$BS7) -> 4 | BU7: =MAX(0,ROUND((BB7-BK7)/$BS7,0)*$BS7) -> 4 | BV7: =MAX(0,ROUND((BC7-BL7)/$BS7,0)*$BS7) -> 2 | BW7: =MAX(0,ROUND((BD7-BM7)/$BS7,0)*$BS7) -> 1 | BX7: =MAX(0,ROUND((BE7-BN7)/$BS7,0)*$BS7) -> 7 | BY7: =MAX(0,ROUND((BF7-BO7)/$BS7,0)*$BS7) -> 2 | BZ7: =MAX(0,ROUND((BG7-BP7)/$BS7,0)*$BS7) -> 3 | CA7: =MAX(0,ROUND((BH7-BQ7)/$BS7,0)*$BS7) -> 2 | CB7: 2 | CC7: =SUM(BT7:CA7) -> 25 | CD7: =CB7-CC7 -> -23
B8: 2 | C8: AC HA | D8: 97888 | E8: RANCHER-STRAW HAT LIGHT | F8: 26 Summer 1 Fashion | G8: FashionFocusStore | H8: 29.95 | I8: 1 | J8: 2 | K8: Y | L8: N | M8: (blank) | N8: Pass | O8: =D8 -> 97888 | P8: AC HA/26-31/No | Q8: =IFERROR(INDEX(Item_Code_allocation_table!$C$4:$I$15,MATCH(Main!$O8,Item_Code_allocation_table!$B$4:$B$15,0),MATCH(Main!Q$6,Item_Code_allocation_table!$C$3:$I$3,0)), INDEX(DPS_Code_allocation_table!$C$4:$I$15,MATCH(Main!$P8,DPS_Code_allocation_table!$B$4:$B$15,0),MATCH(Main!Q$6,DPS_Code_allocation_table!$C$3:$I$3,0))) -> 14 | R8: =IFERROR(INDEX(Item_Code_allocation_table!$C$4:$I$15,MATCH(Main!$O8,Item_Code_allocation_table!$B$4:$B$15,0),MATCH(Main!R$6,Item_Code_allocation_table!$C$3:$I$3,0)), INDEX(DPS_Code_allocation_table!$C$4:$I$15,MATCH(Main!$P8,DPS_Code_allocation_table!$B$4:$B$15,0),MATCH(Main!R$6,DPS_Code_allocation_table!$C$3:$I$3,0))) -> 8 | S8: =IFERROR(INDEX(Item_Code_allocation_table!$C$4:$I$15,MATCH(Main!$O8,Item_Code_allocation_table!$B$4:$B$15,0),MATCH(Main!S$6,Item_Code_allocation_table!$C$3:$I$3,0)), INDEX(DPS_Code_allocation_table!$C$4:$I$15,MATCH(Main!$P8,DPS_Code_allocation_table!$B$4:$B$15,0),MATCH(Main!S$6,DPS_Code_allocation_table!$C$3:$I$3,0))) -> 7 | T8: =IFERROR(INDEX(Item_Code_allocation_table!$C$4:$I$15,MATCH(Main!$O8,Item_Code_allocation_table!$B$4:$B$15,0),MATCH(Main!T$6,Item_Code_allocation_table!$C$3:$I$3,0)), INDEX(DPS_Code_allocation_table!$C$4:$I$15,MATCH(Main!$P8,DPS_Code_allocation_table!$B$4:$B$15,0),MATCH(Main!T$6,DPS_Code_allocation_table!$C$3:$I$3,0))) -> 5 | U8: =IFERROR(INDEX(Item_Code_allocation_table!$C$4:$I$15,MATCH(Main!$O8,Item_Code_allocation_table!$B$4:$B$15,0),MATCH(Main!U$6,Item_Code_allocation_table!$C$3:$I$3,0)), INDEX(DPS_Code_allocation_table!$C$4:$I$15,MATCH(Main!$P8,DPS_Code_allocation_table!$B$4:$B$15,0),MATCH(Main!U$6,DPS_Code_allocation_table!$C$3:$I$3,0))) -> 4 | V8: =IFERROR(INDEX(Item_Code_allocation_table!$C$4:$I$15,MATCH(Main!$O8,Item_Code_allocation_table!$B$4:$B$15,0),MATCH(Main!V$6,Item_Code_allocation_table!$C$3:$I$3,0)), INDEX(DPS_Code_allocation_table!$C$4:$I$15,MATCH(Main!$P8,DPS_Code_allocation_table!$B$4:$B$15,0),MATCH(Main!V$6,DPS_Code_allocation_table!$C$3:$I$3,0))) -> 3 | W8: =IFERROR(INDEX(Item_Code_allocation_table!$C$4:$I$15,MATCH(Main!$O8,Item_Code_allocation_table!$B$4:$B$15,0),MATCH(Main!W$6,Item_Code_allocation_table!$C$3:$I$3,0)), INDEX(DPS_Code_allocation_table!$C$4:$I$15,MATCH(Main!$P8,DPS_Code_allocation_table!$B$4:$B$15,0),MATCH(Main!W$6,DPS_Code_allocation_table!$C$3:$I$3,0))) -> 3 | Y8: =VLOOKUP(C8,DCS_Pattern!B:C,2,FALSE) -> Pattern 02 | Z8: {=_xlfn.XLOOKUP(1,(Store_Group!$B$4:$B$1532=$Y8)*(Store_Group!$C$4:$C$1532=Z$6),Store_Group!$D$4:$D$1532,"")} -> B | AA8: {=_xlfn.XLOOKUP(1,(Store_Group!$B$4:$B$1532=$Y8)*(Store_Group!$C$4:$C$1532=AA$6),Store_Group!$D$4:$D$1532,"")} -> A3 | AB8: {=_xlfn.XLOOKUP(1,(Store_Group!$B$4:$B$1532=$Y8)*(Store_Group!$C$4:$C$1532=AB$6),Store_Group!$D$4:$D$1532,"")} -> C | AC8: {=_xlfn.XLOOKUP(1,(Store_Group!$B$4:$B$1532=$Y8)*(Store_Group!$C$4:$C$1532=AC$6),Store_Group!$D$4:$D$1532,"")} -> C | AD8: {=_xlfn.XLOOKUP(1,(Store_Group!$B$4:$B$1532=$Y8)*(Store_Group!$C$4:$C$1532=AD$6),Store_Group!$D$4:$D$1532,"")} -> A3 | AE8: {=_xlfn.XLOOKUP(1,(Store_Group!$B$4:$B$1532=$Y8)*(Store_Group!$C$4:$C$1532=AE$6),Store_Group!$D$4:$D$1532,"")} -> C | AF8: {=_xlfn.XLOOKUP(1,(Store_Group!$B$4:$B$1532=$Y8)*(Store_Group!$C$4:$C$1532=AF$6),Store_Group!$D$4:$D$1532,"")} -> C | AG8: {=_xlfn.XLOOKUP(1,(Store_Group!$B$4:$B$1532=$Y8)*(Store_Group!$C$4:$C$1532=AG$6),Store_Group!$D$4:$D$1532,"")} -> C | AI8: =INDEX($Q8:$W8,1,MATCH(Z8,$Q$6:$W$6,0)) -> 5 | AJ8: =INDEX($Q8:$W8,1,MATCH(AA8,$Q$6:$W$6,0)) -> 7 | AK8: =INDEX($Q8:$W8,1,MATCH(AB8,$Q$6:$W$6,0)) -> 4 | AL8: =INDEX($Q8:$W8,1,MATCH(AC8,$Q$6:$W$6,0)) -> 4 | AM8: =INDEX($Q8:$W8,1,MATCH(AD8,$Q$6:$W$6,0)) -> 7 | AN8: =INDEX($Q8:$W8,1,MATCH(AE8,$Q$6:$W$6,0)) -> 4 | AO8: =INDEX($Q8:$W8,1,MATCH(AF8,$Q$6:$W$6,0)) -> 4 | AP8: =INDEX($Q8:$W8,1,MATCH(AG8,$Q$6:$W$6,0)) -> 4 | AR8: Y | AS8: Y | AT8: Y | AU8: Y | AV8: Y | AW8: Y | AX8: Y | AY8: Y | BA8: 5 | BB8: 7 | BC8: 4 | BD8: 4 | BE8: 7 | BF8: 4 | BG8: 4 | BH8: 4 | BJ8: 0 | BK8: 3 | BL8: 4 | BM8: 1 | BN8: 4 | BO8: 2 | BP8: 3 | BQ8: 2 | BS8: 1 | BT8: =MAX(0,ROUND((BA8-BJ8)/$BS8,0)*$BS8) -> 5 | BU8: =MAX(0,ROUND((BB8-BK8)/$BS8,0)*$BS8) -> 4 | BV8: =MAX(0,ROUND((BC8-BL8)/$BS8,0)*$BS8) -> 0 | BW8: =MAX(0,ROUND((BD8-BM8)/$BS8,0)*$BS8) -> 3 | BX8: =MAX(0,ROUND((BE8-BN8)/$BS8,0)*$BS8) -> 3 | BY8: =MAX(0,ROUND((BF8-BO8)/$BS8,0)*$BS8) -> 2 | BZ8: =MAX(0,ROUND((BG8-BP8)/$BS8,0)*$BS8) -> 1 | CA8: =MAX(0,ROUND((BH8-BQ8)/$BS8,0)*$BS8) -> 2 | CB8: 1 | CC8: =SUM(BT8:CA8) -> 20 | CD8: =CB8-CC8 -> -19
B9: 3 | C9: CL WO DR | D9: 91815 | E9: DRESS-GRN COTTON GAUZE-S | F9: 25 Summer 1 Fashion | G9: SpringSummer | H9: 49.95 | I9: 1 | J9: 2 | K9: Y | L9: Y | M9: (blank) | N9: Null | O9: =D9 -> 91815 | P9: CL WO DR/46-51/S | Q9: =IFERROR(INDEX(Item_Code_allocation_table!$C$4:$I$15,MATCH(Main!$O9,Item_Code_allocation_table!$B$4:$B$15,0),MATCH(Main!Q$6,Item_Code_allocation_table!$C$3:$I$3,0)), INDEX(DPS_Code_allocation_table!$C$4:$I$15,MATCH(Main!$P9,DPS_Code_allocation_table!$B$4:$B$15,0),MATCH(Main!Q$6,DPS_Code_allocation_table!$C$3:$I$3,0))) -> 12 | R9: =IFERROR(INDEX(Item_Code_allocation_table!$C$4:$I$15,MATCH(Main!$O9,Item_Code_allocation_table!$B$4:$B$15,0),MATCH(Main!R$6,Item_Code_allocation_table!$C$3:$I$3,0)), INDEX(DPS_Code_allocation_table!$C$4:$I$15,MATCH(Main!$P9,DPS_Code_allocation_table!$B$4:$B$15,0),MATCH(Main!R$6,DPS_Code_allocation_table!$C$3:$I$3,0))) -> 6 | S9: =IFERROR(INDEX(Item_Code_allocation_table!$C$4:$I$15,MATCH(Main!$O9,Item_Code_allocation_table!$B$4:$B$15,0),MATCH(Main!S$6,Item_Code_allocation_table!$C$3:$I$3,0)), INDEX(DPS_Code_allocation_table!$C$4:$I$15,MATCH(Main!$P9,DPS_Code_allocation_table!$B$4:$B$15,0),MATCH(Main!S$6,DPS_Code_allocation_table!$C$3:$I$3,0))) -> 5 | T9: =IFERROR(INDEX(Item_Code_allocation_table!$C$4:$I$15,MATCH(Main!$O9,Item_Code_allocation_table!$B$4:$B$15,0),MATCH(Main!T$6,Item_Code_allocation_table!$C$3:$I$3,0)), INDEX(DPS_Code_allocation_table!$C$4:$I$15,MATCH(Main!$P9,DPS_Code_allocation_table!$B$4:$B$15,0),MATCH(Main!T$6,DPS_Code_allocation_table!$C$3:$I$3,0))) -> 4 | U9: =IFERROR(INDEX(Item_Code_allocation_table!$C$4:$I$15,MATCH(Main!$O9,Item_Code_allocation_table!$B$4:$B$15,0),MATCH(Main!U$6,Item_Code_allocation_table!$C$3:$I$3,0)), INDEX(DPS_Code_allocation_table!$C$4:$I$15,MATCH(Main!$P9,DPS_Code_allocation_table!$B$4:$B$15,0),MATCH(Main!U$6,DPS_Code_allocation_table!$C$3:$I$3,0))) -> 4 | V9: =IFERROR(INDEX(Item_Code_allocation_table!$C$4:$I$15,MATCH(Main!$O9,Item_Code_allocation_table!$B$4:$B$15,0),MATCH(Main!V$6,Item_Code_allocation_table!$C$3:$I$3,0)), INDEX(DPS_Code_allocation_table!$C$4:$I$15,MATCH(Main!$P9,DPS_Code_allocation_table!$B$4:$B$15,0),MATCH(Main!V$6,DPS_Code_allocation_table!$C$3:$I$3,0))) -> 3 | W9: =IFERROR(INDEX(Item_Code_allocation_table!$C$4:$I$15,MATCH(Main!$O9,Item_Code_allocation_table!$B$4:$B$15,0),MATCH(Main!W$6,Item_Code_allocation_table!$C$3:$I$3,0)), INDEX(DPS_Code_allocation_table!$C$4:$I$15,MATCH(Main!$P9,DPS_Code_allocation_table!$B$4:$B$15,0),MATCH(Main!W$6,DPS_Code_allocation_table!$C$3:$I$3,0))) -> 2 | Y9: =VLOOKUP(C9,DCS_Pattern!B:C,2,FALSE) -> Pattern 06 | Z9: {=_xlfn.XLOOKUP(1,(Store_Group!$B$4:$B$1532=$Y9)*(Store_Group!$C$4:$C$1532=Z$6),Store_Group!$D$4:$D$1532,"")} -> B | AA9: {=_xlfn.XLOOKUP(1,(Store_Group!$B$4:$B$1532=$Y9)*(Store_Group!$C$4:$C$1532=AA$6),Store_Group!$D$4:$D$1532,"")} -> A3 | AB9: {=_xlfn.XLOOKUP(1,(Store_Group!$B$4:$B$1532=$Y9)*(Store_Group!$C$4:$C$1532=AB$6),Store_Group!$D$4:$D$1532,"")} -> C | AC9: {=_xlfn.XLOOKUP(1,(Store_Group!$B$4:$B$1532=$Y9)*(Store_Group!$C$4:$C$1532=AC$6),Store_Group!$D$4:$D$1532,"")} -> B | AD9: {=_xlfn.XLOOKUP(1,(Store_Group!$B$4:$B$1532=$Y9)*(Store_Group!$C$4:$C$1532=AD$6),Store_Group!$D$4:$D$1532,"")} -> A3 | AE9: {=_xlfn.XLOOKUP(1,(Store_Group!$B$4:$B$1532=$Y9)*(Store_Group!$C$4:$C$1532=AE$6),Store_Group!$D$4:$D$1532,"")} -> B | AF9: {=_xlfn.XLOOKUP(1,(Store_Group!$B$4:$B$1532=$Y9)*(Store_Group!$C$4:$C$1532=AF$6),Store_Group!$D$4:$D$1532,"")} -> C | AG9: {=_xlfn.XLOOKUP(1,(Store_Group!$B$4:$B$1532=$Y9)*(Store_Group!$C$4:$C$1532=AG$6),Store_Group!$D$4:$D$1532,"")} -> C | AI9: =INDEX($Q9:$W9,1,MATCH(Z9,$Q$6:$W$6,0)) -> 4 | AJ9: =INDEX($Q9:$W9,1,MATCH(AA9,$Q$6:$W$6,0)) -> 5 | AK9: =INDEX($Q9:$W9,1,MATCH(AB9,$Q$6:$W$6,0)) -> 4 | AL9: =INDEX($Q9:$W9,1,MATCH(AC9,$Q$6:$W$6,0)) -> 4 | AM9: =INDEX($Q9:$W9,1,MATCH(AD9,$Q$6:$W$6,0)) -> 5 | AN9: =INDEX($Q9:$W9,1,MATCH(AE9,$Q$6:$W$6,0)) -> 4 | AO9: =INDEX($Q9:$W9,1,MATCH(AF9,$Q$6:$W$6,0)) -> 4 | AP9: =INDEX($Q9:$W9,1,MATCH(AG9,$Q$6:$W$6,0)) -> 4 | AR9: Y | AS9: Y | AT9: Y | AU9: Y | AV9: Y | AW9: Y | AX9: Y | AY9: Y | BA9: 4 | BB9: 5 | BC9: 4 | BD9: 4 | BE9: 5 | BF9: 4 | BG9: 4 | BH9: 4 | BJ9: 2 | BK9: 0 | BL9: 4 | BM9: 1 | BN9: 3 | BO9: 1 | BP9: 4 | BQ9: 2 | BS9: 1 | BT9: =MAX(0,ROUND((BA9-BJ9)/$BS9,0)*$BS9) -> 2 | BU9: =MAX(0,ROUND((BB9-BK9)/$BS9,0)*$BS9) -> 5 | BV9: =MAX(0,ROUND((BC9-BL9)/$BS9,0)*$BS9) -> 0 | BW9: =MAX(0,ROUND((BD9-BM9)/$BS9,0)*$BS9) -> 3 | BX9: =MAX(0,ROUND((BE9-BN9)/$BS9,0)*$BS9) -> 2 | BY9: =MAX(0,ROUND((BF9-BO9)/$BS9,0)*$BS9) -> 3 | BZ9: =MAX(0,ROUND((BG9-BP9)/$BS9,0)*$BS9) -> 0 | CA9: =MAX(0,ROUND((BH9-BQ9)/$BS9,0)*$BS9) -> 2 | CB9: 798 | CC9: =SUM(BT9:CA9) -> 17 | CD9: =CB9-CC9 -> 781
B10: 4 | C10: CL WO DR | D10: 91816 | E10: DRESS-GRN COTTON GAUZE-M | F10: 25 Summer 1 Fashion | G10: SpringSummer | H10: 49.95 | I10: 1 | J10: 2 | K10: Y | L10: Y | M10: (blank) | N10: Null | O10: =D10 -> 91816 | P10: CL WO DR/46-51/M | Q10: =IFERROR(INDEX(Item_Code_allocation_table!$C$4:$I$15,MATCH(Main!$O10,Item_Code_allocation_table!$B$4:$B$15,0),MATCH(Main!Q$6,Item_Code_allocation_table!$C$3:$I$3,0)), INDEX(DPS_Code_allocation_table!$C$4:$I$15,MATCH(Main!$P10,DPS_Code_allocation_table!$B$4:$B$15,0),MATCH(Main!Q$6,DPS_Code_allocation_table!$C$3:$I$3,0))) -> 12 | R10: =IFERROR(INDEX(Item_Code_allocation_table!$C$4:$I$15,MATCH(Main!$O10,Item_Code_allocation_table!$B$4:$B$15,0),MATCH(Main!R$6,Item_Code_allocation_table!$C$3:$I$3,0)), INDEX(DPS_Code_allocation_table!$C$4:$I$15,MATCH(Main!$P10,DPS_Code_allocation_table!$B$4:$B$15,0),MATCH(Main!R$6,DPS_Code_allocation_table!$C$3:$I$3,0))) -> 6 | S10: =IFERROR(INDEX(Item_Code_allocation_table!$C$4:$I$15,MATCH(Main!$O10,Item_Code_allocation_table!$B$4:$B$15,0),MATCH(Main!S$6,Item_Code_allocation_table!$C$3:$I$3,0)), INDEX(DPS_Code_allocation_table!$C$4:$I$15,MATCH(Main!$P10,DPS_Code_allocation_table!$B$4:$B$15,0),MATCH(Main!S$6,DPS_Code_allocation_table!$C$3:$I$3,0))) -> 5 | T10: =IFERROR(INDEX(Item_Code_allocation_table!$C$4:$I$15,MATCH(Main!$O10,Item_Code_allocation_table!$B$4:$B$15,0),MATCH(Main!T$6,Item_Code_allocation_table!$C$3:$I$3,0)), INDEX(DPS_Code_allocation_table!$C$4:$I$15,MATCH(Main!$P10,DPS_Code_allocation_table!$B$4:$B$15,0),MATCH(Main!T$6,DPS_Code_allocation_table!$C$3:$I$3,0))) -> 4 | U10: =IFERROR(INDEX(Item_Code_allocation_table!$C$4:$I$15,MATCH(Main!$O10,Item_Code_allocation_table!$B$4:$B$15,0),MATCH(Main!U$6,Item_Code_allocation_table!$C$3:$I$3,0)), INDEX(DPS_Code_allocation_table!$C$4:$I$15,MATCH(Main!$P10,DPS_Code_allocation_table!$B$4:$B$15,0),MATCH(Main!U$6,DPS_Code_allocation_table!$C$3:$I$3,0))) -> 4 | V10: =IFERROR(INDEX(Item_Code_allocation_table!$C$4:$I$15,MATCH(Main!$O10,Item_Code_allocation_table!$B$4:$B$15,0),MATCH(Main!V$6,Item_Code_allocation_table!$C$3:$I$3,0)), INDEX(DPS_Code_allocation_table!$C$4:$I$15,MATCH(Main!$P10,DPS_Code_allocation_table!$B$4:$B$15,0),MATCH(Main!V$6,DPS_Code_allocation_table!$C$3:$I$3,0))) -> 3 | W10: =IFERROR(INDEX(Item_Code_allocation_table!$C$4:$I$15,MATCH(Main!$O10,Item_Code_allocation_table!$B$4:$B$15,0),MATCH(Main!W$6,Item_Code_allocation_table!$C$3:$I$3,0)), INDEX(DPS_Code_allocation_table!$C$4:$I$15,MATCH(Main!$P10,DPS_Code_allocation_table!$B$4:$B$15,0),MATCH(Main!W$6,DPS_Code_allocation_table!$C$3:$I$3,0))) -> 2 | Y10: =VLOOKUP(C10,DCS_Pattern!B:C,2,FALSE) -> Pattern 06 | Z10: {=_xlfn.XLOOKUP(1,(Store_Group!$B$4:$B$1532=$Y10)*(Store_Group!$C$4:$C$1532=Z$6),Store_Group!$D$4:$D$1532,"")} -> B | AA10: {=_xlfn.XLOOKUP(1,(Store_Group!$B$4:$B$1532=$Y10)*(Store_Group!$C$4:$C$1532=AA$6),Store_Group!$D$4:$D$1532,"")} -> A3 | AB10: {=_xlfn.XLOOKUP(1,(Store_Group!$B$4:$B$1532=$Y10)*(Store_Group!$C$4:$C$1532=AB$6),Store_Group!$D$4:$D$1532,"")} -> C | AC10: {=_xlfn.XLOOKUP(1,(Store_Group!$B$4:$B$1532=$Y10)*(Store_Group!$C$4:$C$1532=AC$6),Store_Group!$D$4:$D$1532,"")} -> B | AD10: {=_xlfn.XLOOKUP(1,(Store_Group!$B$4:$B$1532=$Y10)*(Store_Group!$C$4:$C$1532=AD$6),Store_Group!$D$4:$D$1532,"")} -> A3 | AE10: {=_xlfn.XLOOKUP(1,(Store_Group!$B$4:$B$1532=$Y10)*(Store_Group!$C$4:$C$1532=AE$6),Store_Group!$D$4:$D$1532,"")} -> B | AF10: {=_xlfn.XLOOKUP(1,(Store_Group!$B$4:$B$1532=$Y10)*(Store_Group!$C$4:$C$1532=AF$6),Store_Group!$D$4:$D$1532,"")} -> C | AG10: {=_xlfn.XLOOKUP(1,(Store_Group!$B$4:$B$1532=$Y10)*(Store_Group!$C$4:$C$1532=AG$6),Store_Group!$D$4:$D$1532,"")} -> C | AI10: =INDEX($Q10:$W10,1,MATCH(Z10,$Q$6:$W$6,0)) -> 4 | AJ10: =INDEX($Q10:$W10,1,MATCH(AA10,$Q$6:$W$6,0)) -> 5 | AK10: =INDEX($Q10:$W10,1,MATCH(AB10,$Q$6:$W$6,0)) -> 4 | AL10: =INDEX($Q10:$W10,1,MATCH(AC10,$Q$6:$W$6,0)) -> 4 | AM10: =INDEX($Q10:$W10,1,MATCH(AD10,$Q$6:$W$6,0)) -> 5 | AN10: =INDEX($Q10:$W10,1,MATCH(AE10,$Q$6:$W$6,0)) -> 4 | AO10: =INDEX($Q10:$W10,1,MATCH(AF10,$Q$6:$W$6,0)) -> 4 | AP10: =INDEX($Q10:$W10,1,MATCH(AG10,$Q$6:$W$6,0)) -> 4 | AR10: Y | AS10: Y | AT10: Y | AU10: Y | AV10: Y | AW10: Y | AX10: Y | AY10: Y | BA10: 4 | BB10: 5 | BC10: 4 | BD10: 4 | BE10: 5 | BF10: 4 | BG10: 4 | BH10: 4 | BJ10: 1 | BK10: 4 | BL10: 1 | BM10: 4 | BN10: 3 | BO10: 3 | BP10: 1 | BQ10: 3 | BS10: 1 | BT10: =MAX(0,ROUND((BA10-BJ10)/$BS10,0)*$BS10) -> 3 | BU10: =MAX(0,ROUND((BB10-BK10)/$BS10,0)*$BS10) -> 1 | BV10: =MAX(0,ROUND((BC10-BL10)/$BS10,0)*$BS10) -> 3 | BW10: =MAX(0,ROUND((BD10-BM10)/$BS10,0)*$BS10) -> 0 | BX10: =MAX(0,ROUND((BE10-BN10)/$BS10,0)*$BS10) -> 2 | BY10: =MAX(0,ROUND((BF10-BO10)/$BS10,0)*$BS10) -> 1 | BZ10: =MAX(0,ROUND((BG10-BP10)/$BS10,0)*$BS10) -> 3 | CA10: =MAX(0,ROUND((BH10-BQ10)/$BS10,0)*$BS10) -> 1 | CB10: 1311 | CC10: =SUM(BT10:CA10) -> 14 | CD10: =CB10-CC10 -> 1297
B11: 5 | C11: CL WO DR | D11: 91817 | E11: DRESS-GRN COTTON GAUZE-L | F11: 25 Summer 1 Fashion | G11: SpringSummer | H11: 49.95 | I11: 1 | J11: 1 | K11: Y | L11: Y | M11: (blank) | N11: Null | O11: =D11 -> 91817 | P11: CL WO DR/46-51/L | Q11: =IFERROR(INDEX(Item_Code_allocation_table!$C$4:$I$15,MATCH(Main!$O11,Item_Code_allocation_table!$B$4:$B$15,0),MATCH(Main!Q$6,Item_Code_allocation_table!$C$3:$I$3,0)), INDEX(DPS_Code_allocation_table!$C$4:$I$15,MATCH(Main!$P11,DPS_Code_allocation_table!$B$4:$B$15,0),MATCH(Main!Q$6,DPS_Code_allocation_table!$C$3:$I$3,0))) -> 10 | R11: =IFERROR(INDEX(Item_Code_allocation_table!$C$4:$I$15,MATCH(Main!$O11,Item_Code_allocation_table!$B$4:$B$15,0),MATCH(Main!R$6,Item_Code_allocation_table!$C$3:$I$3,0)), INDEX(DPS_Code_allocation_table!$C$4:$I$15,MATCH(Main!$P11,DPS_Code_allocation_table!$B$4:$B$15,0),MATCH(Main!R$6,DPS_Code_allocation_table!$C$3:$I$3,0))) -> 5 | S11: =IFERROR(INDEX(Item_Code_allocation_table!$C$4:$I$15,MATCH(Main!$O11,Item_Code_allocation_table!$B$4:$B$15,0),MATCH(Main!S$6,Item_Code_allocation_table!$C$3:$I$3,0)), INDEX(DPS_Code_allocation_table!$C$4:$I$15,MATCH(Main!$P11,DPS_Code_allocation_table!$B$4:$B$15,0),MATCH(Main!S$6,DPS_Code_allocation_table!$C$3:$I$3,0))) -> 4 | T11: =IFERROR(INDEX(Item_Code_allocation_table!$C$4:$I$15,MATCH(Main!$O11,Item_Code_allocation_table!$B$4:$B$15,0),MATCH(Main!T$6,Item_Code_allocation_table!$C$3:$I$3,0)), INDEX(DPS_Code_allocation_table!$C$4:$I$15,MATCH(Main!$P11,DPS_Code_allocation_table!$B$4:$B$15,0),MATCH(Main!T$6,DPS_Code_allocation_table!$C$3:$I$3,0))) -> 3 | U11: =IFERROR(INDEX(Item_Code_allocation_table!$C$4:$I$15,MATCH(Main!$O11,Item_Code_allocation_table!$B$4:$B$15,0),MATCH(Main!U$6,Item_Code_allocation_table!$C$3:$I$3,0)), INDEX(DPS_Code_allocation_table!$C$4:$I$15,MATCH(Main!$P11,DPS_Code_allocation_table!$B$4:$B$15,0),MATCH(Main!U$6,DPS_Code_allocation_table!$C$3:$I$3,0))) -> 2 | V11: =IFERROR(INDEX(Item_Code_allocation_table!$C$4:$I$15,MATCH(Main!$O11,Item_Code_allocation_table!$B$4:$B$15,0),MATCH(Main!V$6,Item_Code_allocation_table!$C$3:$I$3,0)), INDEX(DPS_Code_allocation_table!$C$4:$I$15,MATCH(Main!$P11,DPS_Code_allocation_table!$B$4:$B$15,0),MATCH(Main!V$6,DPS_Code_allocation_table!$C$3:$I$3,0))) -> 2 | W11: =IFERROR(INDEX(Item_Code_allocation_table!$C$4:$I$15,MATCH(Main!$O11,Item_Code_allocation_table!$B$4:$B$15,0),MATCH(Main!W$6,Item_Code_allocation_table!$C$3:$I$3,0)), INDEX(DPS_Code_allocation_table!$C$4:$I$15,MATCH(Main!$P11,DPS_Code_allocation_table!$B$4:$B$15,0),MATCH(Main!W$6,DPS_Code_allocation_table!$C$3:$I$3,0))) -> 1 | Y11: =VLOOKUP(C11,DCS_Pattern!B:C,2,FALSE) -> Pattern 06 | Z11: {=_xlfn.XLOOKUP(1,(Store_Group!$B$4:$B$1532=$Y11)*(Store_Group!$C$4:$C$1532=Z$6),Store_Group!$D$4:$D$1532,"")} -> B | AA11: {=_xlfn.XLOOKUP(1,(Store_Group!$B$4:$B$1532=$Y11)*(Store_Group!$C$4:$C$1532=AA$6),Store_Group!$D$4:$D$1532,"")} -> A3 | AB11: {=_xlfn.XLOOKUP(1,(Store_Group!$B$4:$B$1532=$Y11)*(Store_Group!$C$4:$C$1532=AB$6),Store_Group!$D$4:$D$1532,"")} -> C | AC11: {=_xlfn.XLOOKUP(1,(Store_Group!$B$4:$B$1532=$Y11)*(Store_Group!$C$4:$C$1532=AC$6),Store_Group!$D$4:$D$1532,"")} -> B | AD11: {=_xlfn.XLOOKUP(1,(Store_Group!$B$4:$B$1532=$Y11)*(Store_Group!$C$4:$C$1532=AD$6),Store_Group!$D$4:$D$1532,"")} -> A3 | AE11: {=_xlfn.XLOOKUP(1,(Store_Group!$B$4:$B$1532=$Y11)*(Store_Group!$C$4:$C$1532=AE$6),Store_Group!$D$4:$D$1532,"")} -> B | AF11: {=_xlfn.XLOOKUP(1,(Store_Group!$B$4:$B$1532=$Y11)*(Store_Group!$C$4:$C$1532=AF$6),Store_Group!$D$4:$D$1532,"")} -> C | AG11: {=_xlfn.XLOOKUP(1,(Store_Group!$B$4:$B$1532=$Y11)*(Store_Group!$C$4:$C$1532=AG$6),Store_Group!$D$4:$D$1532,"")} -> C | AI11: =INDEX($Q11:$W11,1,MATCH(Z11,$Q$6:$W$6,0)) -> 3 | AJ11: =INDEX($Q11:$W11,1,MATCH(AA11,$Q$6:$W$6,0)) -> 4 | AK11: =INDEX($Q11:$W11,1,MATCH(AB11,$Q$6:$W$6,0)) -> 2 | AL11: =INDEX($Q11:$W11,1,MATCH(AC11,$Q$6:$W$6,0)) -> 3 | AM11: =INDEX($Q11:$W11,1,MATCH(AD11,$Q$6:$W$6,0)) -> 4 | AN11: =INDEX($Q11:$W11,1,MATCH(AE11,$Q$6:$W$6,0)) -> 3 | AO11: =INDEX($Q11:$W11,1,MATCH(AF11,$Q$6:$W$6,0)) -> 2 | AP11: =INDEX($Q11:$W11,1,MATCH(AG11,$Q$6:$W$6,0)) -> 2 | AR11: Y | AS11: Y | AT11: Y | AU11: Y | AV11: Y | AW11: Y | AX11: Y | AY11: Y | BA11: 3 | BB11: 4 | BC11: 2 | BD11: 3 | BE11: 4 | BF11: 3 | BG11: 2 | BH11: 2 | BJ11: 1 | BK11: 2 | BL11: 4 | BM11: 2 | BN11: 3 | BO11: 0 | BP11: 1 | BQ11: 2 | BS11: 1 | BT11: =MAX(0,ROUND((BA11-BJ11)/$BS11,0)*$BS11) -> 2 | BU11: =MAX(0,ROUND((BB11-BK11)/$BS11,0)*$BS11) -> 2 | BV11: =MAX(0,ROUND((BC11-BL11)/$BS11,0)*$BS11) -> 0 | BW11: =MAX(0,ROUND((BD11-BM11)/$BS11,0)*$BS11) -> 1 | BX11: =MAX(0,ROUND((BE11-BN11)/$BS11,0)*$BS11) -> 1 | BY11: =MAX(0,ROUND((BF11-BO11)/$BS11,0)*$BS11) -> 3 | BZ11: =MAX(0,ROUND((BG11-BP11)/$BS11,0)*$BS11) -> 1 | CA11: =MAX(0,ROUND((BH11-BQ11)/$BS11,0)*$BS11) -> 0 | CB11: 517 | CC11: =SUM(BT11:CA11) -> 10 | CD11: =CB11-CC11 -> 507
B12: 6 | C12: CL WO DR | D12: 91818 | E12: DRESS-GRN COTTON GAUZE-XL | F12: 25 Summer 1 Fashion | G12: SpringSummer | H12: 49.95 | I12: 1 | J12: 1 | K12: Y | L12: Y | M12: (blank) | N12: Null | O12: =D12 -> 91818 | P12: CL WO DR/46-51/XL | Q12: =IFERROR(INDEX(Item_Code_allocation_table!$C$4:$I$15,MATCH(Main!$O12,Item_Code_allocation_table!$B$4:$B$15,0),MATCH(Main!Q$6,Item_Code_allocation_table!$C$3:$I$3,0)), INDEX(DPS_Code_allocation_table!$C$4:$I$15,MATCH(Main!$P12,DPS_Code_allocation_table!$B$4:$B$15,0),MATCH(Main!Q$6,DPS_Code_allocation_table!$C$3:$I$3,0))) -> 6 | R12: =IFERROR(INDEX(Item_Code_allocation_table!$C$4:$I$15,MATCH(Main!$O12,Item_Code_allocation_table!$B$4:$B$15,0),MATCH(Main!R$6,Item_Code_allocation_table!$C$3:$I$3,0)), INDEX(DPS_Code_allocation_table!$C$4:$I$15,MATCH(Main!$P12,DPS_Code_allocation_table!$B$4:$B$15,0),MATCH(Main!R$6,DPS_Code_allocation_table!$C$3:$I$3,0))) -> 3 | S12: =IFERROR(INDEX(Item_Code_allocation_table!$C$4:$I$15,MATCH(Main!$O12,Item_Code_allocation_table!$B$4:$B$15,0),MATCH(Main!S$6,Item_Code_allocation_table!$C$3:$I$3,0)), INDEX(DPS_Code_allocation_table!$C$4:$I$15,MATCH(Main!$P12,DPS_Code_allocation_table!$B$4:$B$15,0),MATCH(Main!S$6,DPS_Code_allocation_table!$C$3:$I$3,0))) -> 2 | T12: =IFERROR(INDEX(Item_Code_allocation_table!$C$4:$I$15,MATCH(Main!$O12,Item_Code_allocation_table!$B$4:$B$15,0),MATCH(Main!T$6,Item_Code_allocation_table!$C$3:$I$3,0)), INDEX(DPS_Code_allocation_table!$C$4:$I$15,MATCH(Main!$P12,DPS_Code_allocation_table!$B$4:$B$15,0),MATCH(Main!T$6,DPS_Code_allocation_table!$C$3:$I$3,0))) -> 2 | U12: =IFERROR(INDEX(Item_Code_allocation_table!$C$4:$I$15,MATCH(Main!$O12,Item_Code_allocation_table!$B$4:$B$15,0),MATCH(Main!U$6,Item_Code_allocation_table!$C$3:$I$3,0)), INDEX(DPS_Code_allocation_table!$C$4:$I$15,MATCH(Main!$P12,DPS_Code_allocation_table!$B$4:$B$15,0),MATCH(Main!U$6,DPS_Code_allocation_table!$C$3:$I$3,0))) -> 1 | V12: =IFERROR(INDEX(Item_Code_allocation_table!$C$4:$I$15,MATCH(Main!$O12,Item_Code_allocation_table!$B$4:$B$15,0),MATCH(Main!V$6,Item_Code_allocation_table!$C$3:$I$3,0)), INDEX(DPS_Code_allocation_table!$C$4:$I$15,MATCH(Main!$P12,DPS_Code_allocation_table!$B$4:$B$15,0),MATCH(Main!V$6,DPS_Code_allocation_table!$C$3:$I$3,0))) -> 1 | W12: =IFERROR(INDEX(Item_Code_allocation_table!$C$4:$I$15,MATCH(Main!$O12,Item_Code_allocation_table!$B$4:$B$15,0),MATCH(Main!W$6,Item_Code_allocation_table!$C$3:$I$3,0)), INDEX(DPS_Code_allocation_table!$C$4:$I$15,MATCH(Main!$P12,DPS_Code_allocation_table!$B$4:$B$15,0),MATCH(Main!W$6,DPS_Code_allocation_table!$C$3:$I$3,0))) -> 1 | Y12: =VLOOKUP(C12,DCS_Pattern!B:C,2,FALSE) -> Pattern 06 | Z12: {=_xlfn.XLOOKUP(1,(Store_Group!$B$4:$B$1532=$Y12)*(Store_Group!$C$4:$C$1532=Z$6),Store_Group!$D$4:$D$1532,"")} -> B | AA12: {=_xlfn.XLOOKUP(1,(Store_Group!$B$4:$B$1532=$Y12)*(Store_Group!$C$4:$C$1532=AA$6),Store_Group!$D$4:$D$1532,"")} -> A3 | AB12: {=_xlfn.XLOOKUP(1,(Store_Group!$B$4:$B$1532=$Y12)*(Store_Group!$C$4:$C$1532=AB$6),Store_Group!$D$4:$D$1532,"")} -> C | AC12: {=_xlfn.XLOOKUP(1,(Store_Group!$B$4:$B$1532=$Y12)*(Store_Group!$C$4:$C$1532=AC$6),Store_Group!$D$4:$D$1532,"")} -> B | AD12: {=_xlfn.XLOOKUP(1,(Store_Group!$B$4:$B$1532=$Y12)*(Store_Group!$C$4:$C$1532=AD$6),Store_Group!$D$4:$D$1532,"")} -> A3 | AE12: {=_xlfn.XLOOKUP(1,(Store_Group!$B$4:$B$1532=$Y12)*(Store_Group!$C$4:$C$1532=AE$6),Store_Group!$D$4:$D$1532,"")} -> B | AF12: {=_xlfn.XLOOKUP(1,(Store_Group!$B$4:$B$1532=$Y12)*(Store_Group!$C$4:$C$1532=AF$6),Store_Group!$D$4:$D$1532,"")} -> C | AG12: {=_xlfn.XLOOKUP(1,(Store_Group!$B$4:$B$1532=$Y12)*(Store_Group!$C$4:$C$1532=AG$6),Store_Group!$D$4:$D$1532,"")} -> C | AI12: =INDEX($Q12:$W12,1,MATCH(Z12,$Q$6:$W$6,0)) -> 2 | AJ12: =INDEX($Q12:$W12,1,MATCH(AA12,$Q$6:$W$6,0)) -> 2 | AK12: =INDEX($Q12:$W12,1,MATCH(AB12,$Q$6:$W$6,0)) -> 1 | AL12: =INDEX($Q12:$W12,1,MATCH(AC12,$Q$6:$W$6,0)) -> 2 | AM12: =INDEX($Q12:$W12,1,MATCH(AD12,$Q$6:$W$6,0)) -> 2 | AN12: =INDEX($Q12:$W12,1,MATCH(AE12,$Q$6:$W$6,0)) -> 2 | AO12: =INDEX($Q12:$W12,1,MATCH(AF12,$Q$6:$W$6,0)) -> 1 | AP12: =INDEX($Q12:$W12,1,MATCH(AG12,$Q$6:$W$6,0)) -> 1 | AR12: Y | AS12: Y | AT12: Y | AU12: Y | AV12: Y | AW12: Y | AX12: Y | AY12: Y | BA12: 2 | BB12: 2 | BC12: 1 | BD12: 2 | BE12: 2 | BF12: 2 | BG12: 1 | BH12: 1 | BJ12: 4 | BK12: 0 | BL12: 3 | BM12: 0 | BN12: 3 | BO12: 1 | BP12: 0 | BQ12: 4 | BS12: 1 | BT12: =MAX(0,ROUND((BA12-BJ12)/$BS12,0)*$BS12) -> 0 | BU12: =MAX(0,ROUND((BB12-BK12)/$BS12,0)*$BS12) -> 2 | BV12: =MAX(0,ROUND((BC12-BL12)/$BS12,0)*$BS12) -> 0 | BW12: =MAX(0,ROUND((BD12-BM12)/$BS12,0)*$BS12) -> 2 | BX12: =MAX(0,ROUND((BE12-BN12)/$BS12,0)*$BS12) -> 0 | BY12: =MAX(0,ROUND((BF12-BO12)/$BS12,0)*$BS12) -> 1 | BZ12: =MAX(0,ROUND((BG12-BP12)/$BS12,0)*$BS12) -> 1 | CA12: =MAX(0,ROUND((BH12-BQ12)/$BS12,0)*$BS12) -> 0 | CB12: 125 | CC12: =SUM(BT12:CA12) -> 6 | CD12: =CB12-CC12 -> 119
B13: 7 | C13: CL WO DR | D13: 91819 | E13: DRESS-GRN COTTON GAUZE-XXL | F13: 25 Summer 1 Fashion | G13: SpringSummer | H13: 49.95 | I13: 1 | J13: 1 | K13: Y | L13: Y | M13: (blank) | N13: Null | O13: =D13 -> 91819 | P13: CL WO DR/46-51/2X | Q13: =IFERROR(INDEX(Item_Code_allocation_table!$C$4:$I$15,MATCH(Main!$O13,Item_Code_allocation_table!$B$4:$B$15,0),MATCH(Main!Q$6,Item_Code_allocation_table!$C$3:$I$3,0)), INDEX(DPS_Code_allocation_table!$C$4:$I$15,MATCH(Main!$P13,DPS_Code_allocation_table!$B$4:$B$15,0),MATCH(Main!Q$6,DPS_Code_allocation_table!$C$3:$I$3,0))) -> 4 | R13: =IFERROR(INDEX(Item_Code_allocation_table!$C$4:$I$15,MATCH(Main!$O13,Item_Code_allocation_table!$B$4:$B$15,0),MATCH(Main!R$6,Item_Code_allocation_table!$C$3:$I$3,0)), INDEX(DPS_Code_allocation_table!$C$4:$I$15,MATCH(Main!$P13,DPS_Code_allocation_table!$B$4:$B$15,0),MATCH(Main!R$6,DPS_Code_allocation_table!$C$3:$I$3,0))) -> 2 | S13: =IFERROR(INDEX(Item_Code_allocation_table!$C$4:$I$15,MATCH(Main!$O13,Item_Code_allocation_table!$B$4:$B$15,0),MATCH(Main!S$6,Item_Code_allocation_table!$C$3:$I$3,0)), INDEX(DPS_Code_allocation_table!$C$4:$I$15,MATCH(Main!$P13,DPS_Code_allocation_table!$B$4:$B$15,0),MATCH(Main!S$6,DPS_Code_allocation_table!$C$3:$I$3,0))) -> 2 | T13: =IFERROR(INDEX(Item_Code_allocation_table!$C$4:$I$15,MATCH(Main!$O13,Item_Code_allocation_table!$B$4:$B$15,0),MATCH(Main!T$6,Item_Code_allocation_table!$C$3:$I$3,0)), INDEX(DPS_Code_allocation_table!$C$4:$I$15,MATCH(Main!$P13,DPS_Code_allocation_table!$B$4:$B$15,0),MATCH(Main!T$6,DPS_Code_allocation_table!$C$3:$I$3,0))) -> 1 | U13: =IFERROR(INDEX(Item_Code_allocation_table!$C$4:$I$15,MATCH(Main!$O13,Item_Code_allocation_table!$B$4:$B$15,0),MATCH(Main!U$6,Item_Code_allocation_table!$C$3:$I$3,0)), INDEX(DPS_Code_allocation_table!$C$4:$I$15,MATCH(Main!$P13,DPS_Code_allocation_table!$B$4:$B$15,0),MATCH(Main!U$6,DPS_Code_allocation_table!$C$3:$I$3,0))) -> 1 | V13: =IFERROR(INDEX(Item_Code_allocation_table!$C$4:$I$15,MATCH(Main!$O13,Item_Code_allocation_table!$B$4:$B$15,0),MATCH(Main!V$6,Item_Code_allocation_table!$C$3:$I$3,0)), INDEX(DPS_Code_allocation_table!$C$4:$I$15,MATCH(Main!$P13,DPS_Code_allocation_table!$B$4:$B$15,0),MATCH(Main!V$6,DPS_Code_allocation_table!$C$3:$I$3,0))) -> 1 | W13: =IFERROR(INDEX(Item_Code_allocation_table!$C$4:$I$15,MATCH(Main!$O13,Item_Code_allocation_table!$B$4:$B$15,0),MATCH(Main!W$6,Item_Code_allocation_table!$C$3:$I$3,0)), INDEX(DPS_Code_allocation_table!$C$4:$I$15,MATCH(Main!$P13,DPS_Code_allocation_table!$B$4:$B$15,0),MATCH(Main!W$6,DPS_Code_allocation_table!$C$3:$I$3,0))) -> 1 | Y13: =VLOOKUP(C13,DCS_Pattern!B:C,2,FALSE) -> Pattern 06 | Z13: {=_xlfn.XLOOKUP(1,(Store_Group!$B$4:$B$1532=$Y13)*(Store_Group!$C$4:$C$1532=Z$6),Store_Group!$D$4:$D$1532,"")} -> B | AA13: {=_xlfn.XLOOKUP(1,(Store_Group!$B$4:$B$1532=$Y13)*(Store_Group!$C$4:$C$1532=AA$6),Store_Group!$D$4:$D$1532,"")} -> A3 | AB13: {=_xlfn.XLOOKUP(1,(Store_Group!$B$4:$B$1532=$Y13)*(Store_Group!$C$4:$C$1532=AB$6),Store_Group!$D$4:$D$1532,"")} -> C | AC13: {=_xlfn.XLOOKUP(1,(Store_Group!$B$4:$B$1532=$Y13)*(Store_Group!$C$4:$C$1532=AC$6),Store_Group!$D$4:$D$1532,"")} -> B | AD13: {=_xlfn.XLOOKUP(1,(Store_Group!$B$4:$B$1532=$Y13)*(Store_Group!$C$4:$C$1532=AD$6),Store_Group!$D$4:$D$1532,"")} -> A3 | AE13: {=_xlfn.XLOOKUP(1,(Store_Group!$B$4:$B$1532=$Y13)*(Store_Group!$C$4:$C$1532=AE$6),Store_Group!$D$4:$D$1532,"")} -> B | AF13: {=_xlfn.XLOOKUP(1,(Store_Group!$B$4:$B$1532=$Y13)*(Store_Group!$C$4:$C$1532=AF$6),Store_Group!$D$4:$D$1532,"")} -> C | AG13: {=_xlfn.XLOOKUP(1,(Store_Group!$B$4:$B$1532=$Y13)*(Store_Group!$C$4:$C$1532=AG$6),Store_Group!$D$4:$D$1532,"")} -> C | AI13: =INDEX($Q13:$W13,1,MATCH(Z13,$Q$6:$W$6,0)) -> 1 | AJ13: =INDEX($Q13:$W13,1,MATCH(AA13,$Q$6:$W$6,0)) -> 2 | AK13: =INDEX($Q13:$W13,1,MATCH(AB13,$Q$6:$W$6,0)) -> 1 | AL13: =INDEX($Q13:$W13,1,MATCH(AC13,$Q$6:$W$6,0)) -> 1 | AM13: =INDEX($Q13:$W13,1,MATCH(AD13,$Q$6:$W$6,0)) -> 2 | AN13: =INDEX($Q13:$W13,1,MATCH(AE13,$Q$6:$W$6,0)) -> 1 | AO13: =INDEX($Q13:$W13,1,MATCH(AF13,$Q$6:$W$6,0)) -> 1 | AP13: =INDEX($Q13:$W13,1,MATCH(AG13,$Q$6:$W$6,0)) -> 1 | AR13: Y | AS13: Y | AT13: Y | AU13: Y | AV13: Y | AW13: Y | AX13: Y | AY13: Y | BA13: 1 | BB13: 2 | BC13: 1 | BD13: 1 | BE13: 2 | BF13: 1 | BG13: 1 | BH13: 1 | BJ13: 2 | BK13: 1 | BL13: 1 | BM13: 4 | BN13: 4 | BO13: 4 | BP13: 1 | BQ13: 4 | BS13: 1 | BT13: =MAX(0,ROUND((BA13-BJ13)/$BS13,0)*$BS13) -> 0 | BU13: =MAX(0,ROUND((BB13-BK13)/$BS13,0)*$BS13) -> 1 | BV13: =MAX(0,ROUND((BC13-BL13)/$BS13,0)*$BS13) -> 0 | BW13: =MAX(0,ROUND((BD13-BM13)/$BS13,0)*$BS13) -> 0 | BX13: =MAX(0,ROUND((BE13-BN13)/$BS13,0)*$BS13) -> 0 | BY13: =MAX(0,ROUND((BF13-BO13)/$BS13,0)*$BS13) -> 0 | BZ13: =MAX(0,ROUND((BG13-BP13)/$BS13,0)*$BS13) -> 0 | CA13: =MAX(0,ROUND((BH13-BQ13)/$BS13,0)*$BS13) -> 0 | CB13: 43 | CC13: =SUM(BT13:CA13) -> 1 | CD13: =CB13-CC13 -> 42
B14: 8 | C14: AC RB | D14: 90829 | E14: LOC REUSE TOTE-KEY WEST MARINE | F14: (blank) | G14: Reorder | H14: 9.95 | I14: 10 | J14: 8 | K14: Y | L14: N | M14: (blank) | N14: Null | O14: =D14 -> 90829 | P14: AC RB/7-10/No | Q14: =IFERROR(INDEX(Item_Code_allocation_table!$C$4:$I$15,MATCH(Main!$O14,Item_Code_allocation_table!$B$4:$B$15,0),MATCH(Main!Q$6,Item_Code_allocation_table!$C$3:$I$3,0)), INDEX(DPS_Code_allocation_table!$C$4:$I$15,MATCH(Main!$P14,DPS_Code_allocation_table!$B$4:$B$15,0),MATCH(Main!Q$6,DPS_Code_allocation_table!$C$3:$I$3,0))) -> 80 | R14: =IFERROR(INDEX(Item_Code_allocation_table!$C$4:$I$15,MATCH(Main!$O14,Item_Code_allocation_table!$B$4:$B$15,0),MATCH(Main!R$6,Item_Code_allocation_table!$C$3:$I$3,0)), INDEX(DPS_Code_allocation_table!$C$4:$I$15,MATCH(Main!$P14,DPS_Code_allocation_table!$B$4:$B$15,0),MATCH(Main!R$6,DPS_Code_allocation_table!$C$3:$I$3,0))) -> 60 | S14: =IFERROR(INDEX(Item_Code_allocation_table!$C$4:$I$15,MATCH(Main!$O14,Item_Code_allocation_table!$B$4:$B$15,0),MATCH(Main!S$6,Item_Code_allocation_table!$C$3:$I$3,0)), INDEX(DPS_Code_allocation_table!$C$4:$I$15,MATCH(Main!$P14,DPS_Code_allocation_table!$B$4:$B$15,0),MATCH(Main!S$6,DPS_Code_allocation_table!$C$3:$I$3,0))) -> 50 | T14: =IFERROR(INDEX(Item_Code_allocation_table!$C$4:$I$15,MATCH(Main!$O14,Item_Code_allocation_table!$B$4:$B$15,0),MATCH(Main!T$6,Item_Code_allocation_table!$C$3:$I$3,0)), INDEX(DPS_Code_allocation_table!$C$4:$I$15,MATCH(Main!$P14,DPS_Code_allocation_table!$B$4:$B$15,0),MATCH(Main!T$6,DPS_Code_allocation_table!$C$3:$I$3,0))) -> 40 | U14: =IFERROR(INDEX(Item_Code_allocation_table!$C$4:$I$15,MATCH(Main!$O14,Item_Code_allocation_table!$B$4:$B$15,0),MATCH(Main!U$6,Item_Code_allocation_table!$C$3:$I$3,0)), INDEX(DPS_Code_allocation_table!$C$4:$I$15,MATCH(Main!$P14,DPS_Code_allocation_table!$B$4:$B$15,0),MATCH(Main!U$6,DPS_Code_allocation_table!$C$3:$I$3,0))) -> 30 | V14: =IFERROR(INDEX(Item_Code_allocation_table!$C$4:$I$15,MATCH(Main!$O14,Item_Code_allocation_table!$B$4:$B$15,0),MATCH(Main!V$6,Item_Code_allocation_table!$C$3:$I$3,0)), INDEX(DPS_Code_allocation_table!$C$4:$I$15,MATCH(Main!$P14,DPS_Code_allocation_table!$B$4:$B$15,0),MATCH(Main!V$6,DPS_Code_allocation_table!$C$3:$I$3,0))) -> 20 | W14: =IFERROR(INDEX(Item_Code_allocation_table!$C$4:$I$15,MATCH(Main!$O14,Item_Code_allocation_table!$B$4:$B$15,0),MATCH(Main!W$6,Item_Code_allocation_table!$C$3:$I$3,0)), INDEX(DPS_Code_allocation_table!$C$4:$I$15,MATCH(Main!$P14,DPS_Code_allocation_table!$B$4:$B$15,0),MATCH(Main!W$6,DPS_Code_allocation_table!$C$3:$I$3,0))) -> 10 | Y14: =VLOOKUP(C14,DCS_Pattern!B:C,2,FALSE) -> Pattern 01 | Z14: {=_xlfn.XLOOKUP(1,(Store_Group!$B$4:$B$1532=$Y14)*(Store_Group!$C$4:$C$1532=Z$6),Store_Group!$D$4:$D$1532,"")} -> B | AA14: {=_xlfn.XLOOKUP(1,(Store_Group!$B$4:$B$1532=$Y14)*(Store_Group!$C$4:$C$1532=AA$6),Store_Group!$D$4:$D$1532,"")} -> A3 | AB14: {=_xlfn.XLOOKUP(1,(Store_Group!$B$4:$B$1532=$Y14)*(Store_Group!$C$4:$C$1532=AB$6),Store_Group!$D$4:$D$1532,"")} -> C | AC14: {=_xlfn.XLOOKUP(1,(Store_Group!$B$4:$B$1532=$Y14)*(Store_Group!$C$4:$C$1532=AC$6),Store_Group!$D$4:$D$1532,"")} -> C | AD14: {=_xlfn.XLOOKUP(1,(Store_Group!$B$4:$B$1532=$Y14)*(Store_Group!$C$4:$C$1532=AD$6),Store_Group!$D$4:$D$1532,"")} -> A3 | AE14: {=_xlfn.XLOOKUP(1,(Store_Group!$B$4:$B$1532=$Y14)*(Store_Group!$C$4:$C$1532=AE$6),Store_Group!$D$4:$D$1532,"")} -> B | AF14: {=_xlfn.XLOOKUP(1,(Store_Group!$B$4:$B$1532=$Y14)*(Store_Group!$C$4:$C$1532=AF$6),Store_Group!$D$4:$D$1532,"")} -> C | AG14: {=_xlfn.XLOOKUP(1,(Store_Group!$B$4:$B$1532=$Y14)*(Store_Group!$C$4:$C$1532=AG$6),Store_Group!$D$4:$D$1532,"")} -> C | AI14: =INDEX($Q14:$W14,1,MATCH(Z14,$Q$6:$W$6,0)) -> 40 | AJ14: =INDEX($Q14:$W14,1,MATCH(AA14,$Q$6:$W$6,0)) -> 50 | AK14: =INDEX($Q14:$W14,1,MATCH(AB14,$Q$6:$W$6,0)) -> 30 | AL14: =INDEX($Q14:$W14,1,MATCH(AC14,$Q$6:$W$6,0)) -> 30 | AM14: =INDEX($Q14:$W14,1,MATCH(AD14,$Q$6:$W$6,0)) -> 50 | AN14: =INDEX($Q14:$W14,1,MATCH(AE14,$Q$6:$W$6,0)) -> 40 | AO14: =INDEX($Q14:$W14,1,MATCH(AF14,$Q$6:$W$6,0)) -> 30 | AP14: =INDEX($Q14:$W14,1,MATCH(AG14,$Q$6:$W$6,0)) -> 30 | AR14: Y | AS14: Y | AT14: Y | AU14: Y | AV14: Y | AW14: Y | AX14: Y | AY14: Y | BA14: 40 | BB14: 50 | BC14: 30 | BD14: 30 | BE14: 50 | BF14: 40 | BG14: 30 | BH14: 30 | BJ14: 0 | BK14: 2 | BL14: 2 | BM14: 0 | BN14: 1 | BO14: 0 | BP14: 4 | BQ14: 2 | BS14: 10 | BT14: =MAX(0,ROUND((BA14-BJ14)/$BS14,0)*$BS14) -> 40 | BU14: =MAX(0,ROUND((BB14-BK14)/$BS14,0)*$BS14) -> 50 | BV14: =MAX(0,ROUND((BC14-BL14)/$BS14,0)*$BS14) -> 30 | BW14: =MAX(0,ROUND((BD14-BM14)/$BS14,0)*$BS14) -> 30 | BX14: =MAX(0,ROUND((BE14-BN14)/$BS14,0)*$BS14) -> 50 | BY14: =MAX(0,ROUND((BF14-BO14)/$BS14,0)*$BS14) -> 40 | BZ14: =MAX(0,ROUND((BG14-BP14)/$BS14,0)*$BS14) -> 30 | CA14: =MAX(0,ROUND((BH14-BQ14)/$BS14,0)*$BS14) -> 30 | CB14: 540 | CC14: =SUM(BT14:CA14) -> 300 | CD14: =CB14-CC14 -> 240
B15: 9 | C15: AS OI | D15: 3764 | E15: FRAGRANCE OIL-CHINA RAIN | F15: (blank) | G15: Reorder | H15: 4.95 | I15: 18 | J15: 12 | K15: Y | L15: Y | M15: (blank) | N15: (blank) | O15: =D15 -> 3764 | P15: AS OI/3-5/No | Q15: =IFERROR(INDEX(Item_Code_allocation_table!$C$4:$I$15,MATCH(Main!$O15,Item_Code_allocation_table!$B$4:$B$15,0),MATCH(Main!Q$6,Item_Code_allocation_table!$C$3:$I$3,0)), INDEX(DPS_Code_allocation_table!$C$4:$I$15,MATCH(Main!$P15,DPS_Code_allocation_table!$B$4:$B$15,0),MATCH(Main!Q$6,DPS_Code_allocation_table!$C$3:$I$3,0))) -> 24 | R15: =IFERROR(INDEX(Item_Code_allocation_table!$C$4:$I$15,MATCH(Main!$O15,Item_Code_allocation_table!$B$4:$B$15,0),MATCH(Main!R$6,Item_Code_allocation_table!$C$3:$I$3,0)), INDEX(DPS_Code_allocation_table!$C$4:$I$15,MATCH(Main!$P15,DPS_Code_allocation_table!$B$4:$B$15,0),MATCH(Main!R$6,DPS_Code_allocation_table!$C$3:$I$3,0))) -> 20 | S15: =IFERROR(INDEX(Item_Code_allocation_table!$C$4:$I$15,MATCH(Main!$O15,Item_Code_allocation_table!$B$4:$B$15,0),MATCH(Main!S$6,Item_Code_allocation_table!$C$3:$I$3,0)), INDEX(DPS_Code_allocation_table!$C$4:$I$15,MATCH(Main!$P15,DPS_Code_allocation_table!$B$4:$B$15,0),MATCH(Main!S$6,DPS_Code_allocation_table!$C$3:$I$3,0))) -> 20 | T15: =IFERROR(INDEX(Item_Code_allocation_table!$C$4:$I$15,MATCH(Main!$O15,Item_Code_allocation_table!$B$4:$B$15,0),MATCH(Main!T$6,Item_Code_allocation_table!$C$3:$I$3,0)), INDEX(DPS_Code_allocation_table!$C$4:$I$15,MATCH(Main!$P15,DPS_Code_allocation_table!$B$4:$B$15,0),MATCH(Main!T$6,DPS_Code_allocation_table!$C$3:$I$3,0))) -> 18 | U15: =IFERROR(INDEX(Item_Code_allocation_table!$C$4:$I$15,MATCH(Main!$O15,Item_Code_allocation_table!$B$4:$B$15,0),MATCH(Main!U$6,Item_Code_allocation_table!$C$3:$I$3,0)), INDEX(DPS_Code_allocation_table!$C$4:$I$15,MATCH(Main!$P15,DPS_Code_allocation_table!$B$4:$B$15,0),MATCH(Main!U$6,DPS_Code_allocation_table!$C$3:$I$3,0))) -> 16 | V15: =IFERROR(INDEX(Item_Code_allocation_table!$C$4:$I$15,MATCH(Main!$O15,Item_Code_allocation_table!$B$4:$B$15,0),MATCH(Main!V$6,Item_Code_allocation_table!$C$3:$I$3,0)), INDEX(DPS_Code_allocation_table!$C$4:$I$15,MATCH(Main!$P15,DPS_Code_allocation_table!$B$4:$B$15,0),MATCH(Main!V$6,DPS_Code_allocation_table!$C$3:$I$3,0))) -> 12 | W15: =IFERROR(INDEX(Item_Code_allocation_table!$C$4:$I$15,MATCH(Main!$O15,Item_Code_allocation_table!$B$4:$B$15,0),MATCH(Main!W$6,Item_Code_allocation_table!$C$3:$I$3,0)), INDEX(DPS_Code_allocation_table!$C$4:$I$15,MATCH(Main!$P15,DPS_Code_allocation_table!$B$4:$B$15,0),MATCH(Main!W$6,DPS_Code_allocation_table!$C$3:$I$3,0))) -> 12 | Y15: =VLOOKUP(C15,DCS_Pattern!B:C,2,FALSE) -> Pattern 05 | Z15: {=_xlfn.XLOOKUP(1,(Store_Group!$B$4:$B$1532=$Y15)*(Store_Group!$C$4:$C$1532=Z$6),Store_Group!$D$4:$D$1532,"")} -> C | AA15: {=_xlfn.XLOOKUP(1,(Store_Group!$B$4:$B$1532=$Y15)*(Store_Group!$C$4:$C$1532=AA$6),Store_Group!$D$4:$D$1532,"")} -> A2 | AB15: {=_xlfn.XLOOKUP(1,(Store_Group!$B$4:$B$1532=$Y15)*(Store_Group!$C$4:$C$1532=AB$6),Store_Group!$D$4:$D$1532,"")} -> A2 | AC15: {=_xlfn.XLOOKUP(1,(Store_Group!$B$4:$B$1532=$Y15)*(Store_Group!$C$4:$C$1532=AC$6),Store_Group!$D$4:$D$1532,"")} -> C | AD15: {=_xlfn.XLOOKUP(1,(Store_Group!$B$4:$B$1532=$Y15)*(Store_Group!$C$4:$C$1532=AD$6),Store_Group!$D$4:$D$1532,"")} -> A3 | AE15: {=_xlfn.XLOOKUP(1,(Store_Group!$B$4:$B$1532=$Y15)*(Store_Group!$C$4:$C$1532=AE$6),Store_Group!$D$4:$D$1532,"")} -> B | AF15: {=_xlfn.XLOOKUP(1,(Store_Group!$B$4:$B$1532=$Y15)*(Store_Group!$C$4:$C$1532=AF$6),Store_Group!$D$4:$D$1532,"")} -> C | AG15: {=_xlfn.XLOOKUP(1,(Store_Group!$B$4:$B$1532=$Y15)*(Store_Group!$C$4:$C$1532=AG$6),Store_Group!$D$4:$D$1532,"")} -> B | AI15: =INDEX($Q15:$W15,1,MATCH(Z15,$Q$6:$W$6,0)) -> 16 | AJ15: =INDEX($Q15:$W15,1,MATCH(AA15,$Q$6:$W$6,0)) -> 20 | AK15: =INDEX($Q15:$W15,1,MATCH(AB15,$Q$6:$W$6,0)) -> 20 | AL15: =INDEX($Q15:$W15,1,MATCH(AC15,$Q$6:$W$6,0)) -> 16 | AM15: =INDEX($Q15:$W15,1,MATCH(AD15,$Q$6:$W$6,0)) -> 20 | AN15: =INDEX($Q15:$W15,1,MATCH(AE15,$Q$6:$W$6,0)) -> 18 | AO15: =INDEX($Q15:$W15,1,MATCH(AF15,$Q$6:$W$6,0)) -> 16 | AP15: =INDEX($Q15:$W15,1,MATCH(AG15,$Q$6:$W$6,0)) -> 18 | AR15: Y | AS15: Y | AT15: Y | AU15: Y | AV15: Y | AW15: Y | AX15: Y | AY15: Y | BA15: 16 | BB15: 20 | BC15: 20 | BD15: 16 | BE15: 20 | BF15: 18 | BG15: 16 | BH15: 18 | BJ15: 3 | BK15: 0 | BL15: 4 | BM15: 4 | BN15: 4 | BO15: 2 | BP15: 2 | BQ15: 0 | BS15: 18 | BT15: =MAX(0,ROUND((BA15-BJ15)/$BS15,0)*$BS15) -> 18 | BU15: =MAX(0,ROUND((BB15-BK15)/$BS15,0)*$BS15) -> 18 | BV15: =MAX(0,ROUND((BC15-BL15)/$BS15,0)*$BS15) -> 18 | BW15: =MAX(0,ROUND((BD15-BM15)/$BS15,0)*$BS15) -> 18 | BX15: =MAX(0,ROUND((BE15-BN15)/$BS15,0)*$BS15) -> 18 | BY15: =MAX(0,ROUND((BF15-BO15)/$BS15,0)*$BS15) -> 18 | BZ15: =MAX(0,ROUND((BG15-BP15)/$BS15,0)*$BS15) -> 18 | CA15: =MAX(0,ROUND((BH15-BQ15)/$BS15,0)*$BS15) -> 18 | CB15: 918 | CC15: =SUM(BT15:CA15) -> 144 | CD15: =CB15-CC15 -> 774
B16: 10 | C16: IM BK | D16: 59285 | E16: JOURNAL-LTHR-CHAKRAS-BRN-XL | F16: (blank) | G16: Reorder | H16: 99.95 | I16: 2 | J16: 2 | K16: Y | L16: Y | M16: (blank) | N16: (blank) | O16: =D16 -> 59285 | P16: IM BK/91-101/No | Q16: =IFERROR(INDEX(Item_Code_allocation_table!$C$4:$I$15,MATCH(Main!$O16,Item_Code_allocation_table!$B$4:$B$15,0),MATCH(Main!Q$6,Item_Code_allocation_table!$C$3:$I$3,0)), INDEX(DPS_Code_allocation_table!$C$4:$I$15,MATCH(Main!$P16,DPS_Code_allocation_table!$B$4:$B$15,0),MATCH(Main!Q$6,DPS_Code_allocation_table!$C$3:$I$3,0))) -> 3 | R16: =IFERROR(INDEX(Item_Code_allocation_table!$C$4:$I$15,MATCH(Main!$O16,Item_Code_allocation_table!$B$4:$B$15,0),MATCH(Main!R$6,Item_Code_allocation_table!$C$3:$I$3,0)), INDEX(DPS_Code_allocation_table!$C$4:$I$15,MATCH(Main!$P16,DPS_Code_allocation_table!$B$4:$B$15,0),MATCH(Main!R$6,DPS_Code_allocation_table!$C$3:$I$3,0))) -> 2 | S16: =IFERROR(INDEX(Item_Code_allocation_table!$C$4:$I$15,MATCH(Main!$O16,Item_Code_allocation_table!$B$4:$B$15,0),MATCH(Main!S$6,Item_Code_allocation_table!$C$3:$I$3,0)), INDEX(DPS_Code_allocation_table!$C$4:$I$15,MATCH(Main!$P16,DPS_Code_allocation_table!$B$4:$B$15,0),MATCH(Main!S$6,DPS_Code_allocation_table!$C$3:$I$3,0))) -> 2 | T16: =IFERROR(INDEX(Item_Code_allocation_table!$C$4:$I$15,MATCH(Main!$O16,Item_Code_allocation_table!$B$4:$B$15,0),MATCH(Main!T$6,Item_Code_allocation_table!$C$3:$I$3,0)), INDEX(DPS_Code_allocation_table!$C$4:$I$15,MATCH(Main!$P16,DPS_Code_allocation_table!$B$4:$B$15,0),MATCH(Main!T$6,DPS_Code_allocation_table!$C$3:$I$3,0))) -> 2 | U16: =IFERROR(INDEX(Item_Code_allocation_table!$C$4:$I$15,MATCH(Main!$O16,Item_Code_allocation_table!$B$4:$B$15,0),MATCH(Main!U$6,Item_Code_allocation_table!$C$3:$I$3,0)), INDEX(DPS_Code_allocation_table!$C$4:$I$15,MATCH(Main!$P16,DPS_Code_allocation_table!$B$4:$B$15,0),MATCH(Main!U$6,DPS_Code_allocation_table!$C$3:$I$3,0))) -> 2 | V16: =IFERROR(INDEX(Item_Code_allocation_table!$C$4:$I$15,MATCH(Main!$O16,Item_Code_allocation_table!$B$4:$B$15,0),MATCH(Main!V$6,Item_Code_allocation_table!$C$3:$I$3,0)), INDEX(DPS_Code_allocation_table!$C$4:$I$15,MATCH(Main!$P16,DPS_Code_allocation_table!$B$4:$B$15,0),MATCH(Main!V$6,DPS_Code_allocation_table!$C$3:$I$3,0))) -> 1 | W16: =IFERROR(INDEX(Item_Code_allocation_table!$C$4:$I$15,MATCH(Main!$O16,Item_Code_allocation_table!$B$4:$B$15,0),MATCH(Main!W$6,Item_Code_allocation_table!$C$3:$I$3,0)), INDEX(DPS_Code_allocation_table!$C$4:$I$15,MATCH(Main!$P16,DPS_Code_allocation_table!$B$4:$B$15,0),MATCH(Main!W$6,DPS_Code_allocation_table!$C$3:$I$3,0))) -> 1 | Y16: =VLOOKUP(C16,DCS_Pattern!B:C,2,FALSE) -> Pattern 10 | Z16: {=_xlfn.XLOOKUP(1,(Store_Group!$B$4:$B$1532=$Y16)*(Store_Group!$C$4:$C$1532=Z$6),Store_Group!$D$4:$D$1532,"")} -> C | AA16: {=_xlfn.XLOOKUP(1,(Store_Group!$B$4:$B$1532=$Y16)*(Store_Group!$C$4:$C$1532=AA$6),Store_Group!$D$4:$D$1532,"")} -> B | AB16: {=_xlfn.XLOOKUP(1,(Store_Group!$B$4:$B$1532=$Y16)*(Store_Group!$C$4:$C$1532=AB$6),Store_Group!$D$4:$D$1532,"")} -> B | AC16: {=_xlfn.XLOOKUP(1,(Store_Group!$B$4:$B$1532=$Y16)*(Store_Group!$C$4:$C$1532=AC$6),Store_Group!$D$4:$D$1532,"")} -> C | AD16: {=_xlfn.XLOOKUP(1,(Store_Group!$B$4:$B$1532=$Y16)*(Store_Group!$C$4:$C$1532=AD$6),Store_Group!$D$4:$D$1532,"")} -> A3 | AE16: {=_xlfn.XLOOKUP(1,(Store_Group!$B$4:$B$1532=$Y16)*(Store_Group!$C$4:$C$1532=AE$6),Store_Group!$D$4:$D$1532,"")} -> B | AF16: {=_xlfn.XLOOKUP(1,(Store_Group!$B$4:$B$1532=$Y16)*(Store_Group!$C$4:$C$1532=AF$6),Store_Group!$D$4:$D$1532,"")} -> D | AG16: {=_xlfn.XLOOKUP(1,(Store_Group!$B$4:$B$1532=$Y16)*(Store_Group!$C$4:$C$1532=AG$6),Store_Group!$D$4:$D$1532,"")} -> C | AI16: =INDEX($Q16:$W16,1,MATCH(Z16,$Q$6:$W$6,0)) -> 2 | AJ16: =INDEX($Q16:$W16,1,MATCH(AA16,$Q$6:$W$6,0)) -> 2 | AK16: =INDEX($Q16:$W16,1,MATCH(AB16,$Q$6:$W$6,0)) -> 2 | AL16: =INDEX($Q16:$W16,1,MATCH(AC16,$Q$6:$W$6,0)) -> 2 | AM16: =INDEX($Q16:$W16,1,MATCH(AD16,$Q$6:$W$6,0)) -> 2 | AN16: =INDEX($Q16:$W16,1,MATCH(AE16,$Q$6:$W$6,0)) -> 2 | AO16: =INDEX($Q16:$W16,1,MATCH(AF16,$Q$6:$W$6,0)) -> 1 | AP16: =INDEX($Q16:$W16,1,MATCH(AG16,$Q$6:$W$6,0)) -> 2 | AR16: Y | AS16: Y | AT16: Y | AU16: Y | AV16: Y | AW16: Y | AX16: Y | AY16: Y | BA16: 2 | BB16: 2 | BC16: 2 | BD16: 2 | BE16: 2 | BF16: 2 | BG16: 1 | BH16: 2 | BJ16: 4 | BK16: 1 | BL16: 3 | BM16: 4 | BN16: 0 | BO16: 4 | BP16: 1 | BQ16: 3 | BS16: 2 | BT16: =MAX(0,ROUND((BA16-BJ16)/$BS16,0)*$BS16) -> 0 | BU16: =MAX(0,ROUND((BB16-BK16)/$BS16,0)*$BS16) -> 2 | BV16: =MAX(0,ROUND((BC16-BL16)/$BS16,0)*$BS16) -> 0 | BW16: =MAX(0,ROUND((BD16-BM16)/$BS16,0)*$BS16) -> 0 | BX16: =MAX(0,ROUND((BE16-BN16)/$BS16,0)*$BS16) -> 2 | BY16: =MAX(0,ROUND((BF16-BO16)/$BS16,0)*$BS16) -> 0 | BZ16: =MAX(0,ROUND((BG16-BP16)/$BS16,0)*$BS16) -> 0 | CA16: =MAX(0,ROUND((BH16-BQ16)/$BS16,0)*$BS16) -> 0 | CB16: 102 | CC16: =SUM(BT16:CA16) -> 4 | CD16: =CB16-CC16 -> 98
B17: 11 | C17: IM GF | D17: 7722 | E17: INSTRUMENT-KARIMBA-NATURAL | F17: (blank) | G17: Staple | H17: 12.95 | I17: 12 | J17: 8 | K17: Y | L17: Y | M17: (blank) | N17: (blank) | O17: =D17 -> 7722 | P17: IM GF/10-13/No | Q17: =IFERROR(INDEX(Item_Code_allocation_table!$C$4:$I$15,MATCH(Main!$O17,Item_Code_allocation_table!$B$4:$B$15,0),MATCH(Main!Q$6,Item_Code_allocation_table!$C$3:$I$3,0)), INDEX(DPS_Code_allocation_table!$C$4:$I$15,MATCH(Main!$P17,DPS_Code_allocation_table!$B$4:$B$15,0),MATCH(Main!Q$6,DPS_Code_allocation_table!$C$3:$I$3,0))) -> 18 | R17: =IFERROR(INDEX(Item_Code_allocation_table!$C$4:$I$15,MATCH(Main!$O17,Item_Code_allocation_table!$B$4:$B$15,0),MATCH(Main!R$6,Item_Code_allocation_table!$C$3:$I$3,0)), INDEX(DPS_Code_allocation_table!$C$4:$I$15,MATCH(Main!$P17,DPS_Code_allocation_table!$B$4:$B$15,0),MATCH(Main!R$6,DPS_Code_allocation_table!$C$3:$I$3,0))) -> 12 | S17: =IFERROR(INDEX(Item_Code_allocation_table!$C$4:$I$15,MATCH(Main!$O17,Item_Code_allocation_table!$B$4:$B$15,0),MATCH(Main!S$6,Item_Code_allocation_table!$C$3:$I$3,0)), INDEX(DPS_Code_allocation_table!$C$4:$I$15,MATCH(Main!$P17,DPS_Code_allocation_table!$B$4:$B$15,0),MATCH(Main!S$6,DPS_Code_allocation_table!$C$3:$I$3,0))) -> 10 | T17: =IFERROR(INDEX(Item_Code_allocation_table!$C$4:$I$15,MATCH(Main!$O17,Item_Code_allocation_table!$B$4:$B$15,0),MATCH(Main!T$6,Item_Code_allocation_table!$C$3:$I$3,0)), INDEX(DPS_Code_allocation_table!$C$4:$I$15,MATCH(Main!$P17,DPS_Code_allocation_table!$B$4:$B$15,0),MATCH(Main!T$6,DPS_Code_allocation_table!$C$3:$I$3,0))) -> 8 | U17: =IFERROR(INDEX(Item_Code_allocation_table!$C$4:$I$15,MATCH(Main!$O17,Item_Code_allocation_table!$B$4:$B$15,0),MATCH(Main!U$6,Item_Code_allocation_table!$C$3:$I$3,0)), INDEX(DPS_Code_allocation_table!$C$4:$I$15,MATCH(Main!$P17,DPS_Code_allocation_table!$B$4:$B$15,0),MATCH(Main!U$6,DPS_Code_allocation_table!$C$3:$I$3,0))) -> 6 | V17: =IFERROR(INDEX(Item_Code_allocation_table!$C$4:$I$15,MATCH(Main!$O17,Item_Code_allocation_table!$B$4:$B$15,0),MATCH(Main!V$6,Item_Code_allocation_table!$C$3:$I$3,0)), INDEX(DPS_Code_allocation_table!$C$4:$I$15,MATCH(Main!$P17,DPS_Code_allocation_table!$B$4:$B$15,0),MATCH(Main!V$6,DPS_Code_allocation_table!$C$3:$I$3,0))) -> 5 | W17: =IFERROR(INDEX(Item_Code_allocation_table!$C$4:$I$15,MATCH(Main!$O17,Item_Code_allocation_table!$B$4:$B$15,0),MATCH(Main!W$6,Item_Code_allocation_table!$C$3:$I$3,0)), INDEX(DPS_Code_allocation_table!$C$4:$I$15,MATCH(Main!$P17,DPS_Code_allocation_table!$B$4:$B$15,0),MATCH(Main!W$6,DPS_Code_allocation_table!$C$3:$I$3,0))) -> 4 | Y17: =VLOOKUP(C17,DCS_Pattern!B:C,2,FALSE) -> Pattern 10 | Z17: {=_xlfn.XLOOKUP(1,(Store_Group!$B$4:$B$1532=$Y17)*(Store_Group!$C$4:$C$1532=Z$6),Store_Group!$D$4:$D$1532,"")} -> C | AA17: {=_xlfn.XLOOKUP(1,(Store_Group!$B$4:$B$1532=$Y17)*(Store_Group!$C$4:$C$1532=AA$6),Store_Group!$D$4:$D$1532,"")} -> B | AB17: {=_xlfn.XLOOKUP(1,(Store_Group!$B$4:$B$1532=$Y17)*(Store_Group!$C$4:$C$1532=AB$6),Store_Group!$D$4:$D$1532,"")} -> B | AC17: {=_xlfn.XLOOKUP(1,(Store_Group!$B$4:$B$1532=$Y17)*(Store_Group!$C$4:$C$1532=AC$6),Store_Group!$D$4:$D$1532,"")} -> C | AD17: {=_xlfn.XLOOKUP(1,(Store_Group!$B$4:$B$1532=$Y17)*(Store_Group!$C$4:$C$1532=AD$6),Store_Group!$D$4:$D$1532,"")} -> A3 | AE17: {=_xlfn.XLOOKUP(1,(Store_Group!$B$4:$B$1532=$Y17)*(Store_Group!$C$4:$C$1532=AE$6),Store_Group!$D$4:$D$1532,"")} -> B | AF17: {=_xlfn.XLOOKUP(1,(Store_Group!$B$4:$B$1532=$Y17)*(Store_Group!$C$4:$C$1532=AF$6),Store_Group!$D$4:$D$1532,"")} -> D | AG17: {=_xlfn.XLOOKUP(1,(Store_Group!$B$4:$B$1532=$Y17)*(Store_Group!$C$4:$C$1532=AG$6),Store_Group!$D$4:$D$1532,"")} -> C | AI17: =INDEX($Q17:$W17,1,MATCH(Z17,$Q$6:$W$6,0)) -> 6 | AJ17: =INDEX($Q17:$W17,1,MATCH(AA17,$Q$6:$W$6,0)) -> 8 | AK17: =INDEX($Q17:$W17,1,MATCH(AB17,$Q$6:$W$6,0)) -> 8 | AL17: =INDEX($Q17:$W17,1,MATCH(AC17,$Q$6:$W$6,0)) -> 6 | AM17: =INDEX($Q17:$W17,1,MATCH(AD17,$Q$6:$W$6,0)) -> 10 | AN17: =INDEX($Q17:$W17,1,MATCH(AE17,$Q$6:$W$6,0)) -> 8 | AO17: =INDEX($Q17:$W17,1,MATCH(AF17,$Q$6:$W$6,0)) -> 5 | AP17: =INDEX($Q17:$W17,1,MATCH(AG17,$Q$6:$W$6,0)) -> 6 | AR17: N | AS17: Y | AT17: Y | AU17: Y | AV17: Y | AW17: Y | AX17: Y | AY17: Y | BA17: 0 | BB17: 8 | BC17: 8 | BD17: 6 | BE17: 10 | BF17: 8 | BG17: 5 | BH17: 6 | BJ17: 1 | BK17: 2 | BL17: 4 | BM17: 3 | BN17: 3 | BO17: 2 | BP17: 4 | BQ17: 3 | BS17: 12 | BT17: =MAX(0,ROUND((BA17-BJ17)/$BS17,0)*$BS17) -> 0 | BU17: =MAX(0,ROUND((BB17-BK17)/$BS17,0)*$BS17) -> 12 | BV17: =MAX(0,ROUND((BC17-BL17)/$BS17,0)*$BS17) -> 0 | BW17: =MAX(0,ROUND((BD17-BM17)/$BS17,0)*$BS17) -> 0 | BX17: =MAX(0,ROUND((BE17-BN17)/$BS17,0)*$BS17) -> 12 | BY17: =MAX(0,ROUND((BF17-BO17)/$BS17,0)*$BS17) -> 12 | BZ17: =MAX(0,ROUND((BG17-BP17)/$BS17,0)*$BS17) -> 0 | CA17: =MAX(0,ROUND((BH17-BQ17)/$BS17,0)*$BS17) -> 0 | CB17: 960 | CC17: =SUM(BT17:CA17) -> 36 | CD17: =CB17-CC17 -> 924
B18: 12 | C18: JE WO BR | D18: 9646 | E18: COPPER BRACELETS | F18: (blank) | G18: Staple | H18: 5.95 | I18: 12 | J18: 30 | K18: Y | L18: N | M18: (blank) | N18: (blank) | O18: =D18 -> 9646 | P18: JE WO BR/5-7/No | Q18: =IFERROR(INDEX(Item_Code_allocation_table!$C$4:$I$15,MATCH(Main!$O18,Item_Code_allocation_table!$B$4:$B$15,0),MATCH(Main!Q$6,Item_Code_allocation_table!$C$3:$I$3,0)), INDEX(DPS_Code_allocation_table!$C$4:$I$15,MATCH(Main!$P18,DPS_Code_allocation_table!$B$4:$B$15,0),MATCH(Main!Q$6,DPS_Code_allocation_table!$C$3:$I$3,0))) -> 20 | R18: =IFERROR(INDEX(Item_Code_allocation_table!$C$4:$I$15,MATCH(Main!$O18,Item_Code_allocation_table!$B$4:$B$15,0),MATCH(Main!R$6,Item_Code_allocation_table!$C$3:$I$3,0)), INDEX(DPS_Code_allocation_table!$C$4:$I$15,MATCH(Main!$P18,DPS_Code_allocation_table!$B$4:$B$15,0),MATCH(Main!R$6,DPS_Code_allocation_table!$C$3:$I$3,0))) -> 16 | S18: =IFERROR(INDEX(Item_Code_allocation_table!$C$4:$I$15,MATCH(Main!$O18,Item_Code_allocation_table!$B$4:$B$15,0),MATCH(Main!S$6,Item_Code_allocation_table!$C$3:$I$3,0)), INDEX(DPS_Code_allocation_table!$C$4:$I$15,MATCH(Main!$P18,DPS_Code_allocation_table!$B$4:$B$15,0),MATCH(Main!S$6,DPS_Code_allocation_table!$C$3:$I$3,0))) -> 12 | T18: =IFERROR(INDEX(Item_Code_allocation_table!$C$4:$I$15,MATCH(Main!$O18,Item_Code_allocation_table!$B$4:$B$15,0),MATCH(Main!T$6,Item_Code_allocation_table!$C$3:$I$3,0)), INDEX(DPS_Code_allocation_table!$C$4:$I$15,MATCH(Main!$P18,DPS_Code_allocation_table!$B$4:$B$15,0),MATCH(Main!T$6,DPS_Code_allocation_table!$C$3:$I$3,0))) -> 10 | U18: =IFERROR(INDEX(Item_Code_allocation_table!$C$4:$I$15,MATCH(Main!$O18,Item_Code_allocation_table!$B$4:$B$15,0),MATCH(Main!U$6,Item_Code_allocation_table!$C$3:$I$3,0)), INDEX(DPS_Code_allocation_table!$C$4:$I$15,MATCH(Main!$P18,DPS_Code_allocation_table!$B$4:$B$15,0),MATCH(Main!U$6,DPS_Code_allocation_table!$C$3:$I$3,0))) -> 10 | V18: =IFERROR(INDEX(Item_Code_allocation_table!$C$4:$I$15,MATCH(Main!$O18,Item_Code_allocation_table!$B$4:$B$15,0),MATCH(Main!V$6,Item_Code_allocation_table!$C$3:$I$3,0)), INDEX(DPS_Code_allocation_table!$C$4:$I$15,MATCH(Main!$P18,DPS_Code_allocation_table!$B$4:$B$15,0),MATCH(Main!V$6,DPS_Code_allocation_table!$C$3:$I$3,0))) -> 8 | W18: =IFERROR(INDEX(Item_Code_allocation_table!$C$4:$I$15,MATCH(Main!$O18,Item_Code_allocation_table!$B$4:$B$15,0),MATCH(Main!W$6,Item_Code_allocation_table!$C$3:$I$3,0)), INDEX(DPS_Code_allocation_table!$C$4:$I$15,MATCH(Main!$P18,DPS_Code_allocation_table!$B$4:$B$15,0),MATCH(Main!W$6,DPS_Code_allocation_table!$C$3:$I$3,0))) -> 6 | Y18: =VLOOKUP(C18,DCS_Pattern!B:C,2,FALSE) -> Pattern 11 | Z18: {=_xlfn.XLOOKUP(1,(Store_Group!$B$4:$B$1532=$Y18)*(Store_Group!$C$4:$C$1532=Z$6),Store_Group!$D$4:$D$1532,"")} -> C | AA18: {=_xlfn.XLOOKUP(1,(Store_Group!$B$4:$B$1532=$Y18)*(Store_Group!$C$4:$C$1532=AA$6),Store_Group!$D$4:$D$1532,"")} -> A3 | AB18: {=_xlfn.XLOOKUP(1,(Store_Group!$B$4:$B$1532=$Y18)*(Store_Group!$C$4:$C$1532=AB$6),Store_Group!$D$4:$D$1532,"")} -> B | AC18: {=_xlfn.XLOOKUP(1,(Store_Group!$B$4:$B$1532=$Y18)*(Store_Group!$C$4:$C$1532=AC$6),Store_Group!$D$4:$D$1532,"")} -> C | AD18: {=_xlfn.XLOOKUP(1,(Store_Group!$B$4:$B$1532=$Y18)*(Store_Group!$C$4:$C$1532=AD$6),Store_Group!$D$4:$D$1532,"")} -> A3 | AE18: {=_xlfn.XLOOKUP(1,(Store_Group!$B$4:$B$1532=$Y18)*(Store_Group!$C$4:$C$1532=AE$6),Store_Group!$D$4:$D$1532,"")} -> B | AF18: {=_xlfn.XLOOKUP(1,(Store_Group!$B$4:$B$1532=$Y18)*(Store_Group!$C$4:$C$1532=AF$6),Store_Group!$D$4:$D$1532,"")} -> C | AG18: {=_xlfn.XLOOKUP(1,(Store_Group!$B$4:$B$1532=$Y18)*(Store_Group!$C$4:$C$1532=AG$6),Store_Group!$D$4:$D$1532,"")} -> B | AI18: =INDEX($Q18:$W18,1,MATCH(Z18,$Q$6:$W$6,0)) -> 10 | AJ18: =INDEX($Q18:$W18,1,MATCH(AA18,$Q$6:$W$6,0)) -> 12 | AK18: =INDEX($Q18:$W18,1,MATCH(AB18,$Q$6:$W$6,0)) -> 10 | AL18: =INDEX($Q18:$W18,1,MATCH(AC18,$Q$6:$W$6,0)) -> 10 | AM18: =INDEX($Q18:$W18,1,MATCH(AD18,$Q$6:$W$6,0)) -> 12 | AN18: =INDEX($Q18:$W18,1,MATCH(AE18,$Q$6:$W$6,0)) -> 10 | AO18: =INDEX($Q18:$W18,1,MATCH(AF18,$Q$6:$W$6,0)) -> 10 | AP18: =INDEX($Q18:$W18,1,MATCH(AG18,$Q$6:$W$6,0)) -> 10 | AR18: Y | AS18: Y | AT18: Y | AU18: Y | AV18: Y | AW18: Y | AX18: Y | AY18: Y | BA18: 10 | BB18: 12 | BC18: 10 | BD18: 10 | BE18: 12 | BF18: 10 | BG18: 10 | BH18: 10 | BJ18: 0 | BK18: 2 | BL18: 3 | BM18: 4 | BN18: 0 | BO18: 0 | BP18: 1 | BQ18: 3 | BS18: 12 | BT18: =MAX(0,ROUND((BA18-BJ18)/$BS18,0)*$BS18) -> 12 | BU18: =MAX(0,ROUND((BB18-BK18)/$BS18,0)*$BS18) -> 12 | BV18: =MAX(0,ROUND((BC18-BL18)/$BS18,0)*$BS18) -> 12 | BW18: =MAX(0,ROUND((BD18-BM18)/$BS18,0)*$BS18) -> 12 | BX18: =MAX(0,ROUND((BE18-BN18)/$BS18,0)*$BS18) -> 12 | BY18: =MAX(0,ROUND((BF18-BO18)/$BS18,0)*$BS18) -> 12 | BZ18: =MAX(0,ROUND((BG18-BP18)/$BS18,0)*$BS18) -> 12 | CA18: =MAX(0,ROUND((BH18-BQ18)/$BS18,0)*$BS18) -> 12 | CB18: 996 | CC18: =SUM(BT18:CA18) -> 96 | CD18: =CB18-CC18 -> 900
C20: Steps:
C21: 1) Create the DPS Code (department, price & size code)
C22: 2) Complete the groups allocation (uses 2 tables)
C23: Look first for the Item Code allocation table, then look for the DPS Code allocation table.
C24: If qty allocated of any group < MDQ then convert to MDQ.
C25: 3) Enter the DCS pattern (use the DCS_Pattern table)
C26: 4) Allocate based on the groups each store belongs to (use the table Store_Group)
C27: 5) Look for the exclusions rules and blockings
C28: 6) Deduct the Qtys OH+TI and allocate based on the Case Qty
C29: 7) Adjust for the negatives (2 adjustments)
C30: First adjustment: decrease qtys of all groups by a percentage until the "Back stock after alloc" is > -60.
